Workbook

Sheet 2009
A1: CASES MOVED PER MONTH | Q1: AS OF 1/3/09
A2: Wine | B2: Year | C2: Jan | D2: Feb | E2: Mar | F2: Apr | G2: May | H2: Jun | I2: Jul | J2: Aug | K2: Sep | L2: Oct | M2: Nov | N2: Dec | O2: Totals | P2: Avg | Q2: BOY Inventory | R2: Months Left | S2: Inven to date
A3: Ameritage Reserve | B3: 2006 | C3: 15 | D3: 14 | E3: 15 | F3: 16 | O3: =SUM(C3:N3) -> 60 | P3: =AVERAGE(C3:N3) -> 15 | Q3: 60 | R3: =S3/P3 -> 0 | S3: =SUM(Q3-O3) -> 0
A4: Ameritage | B4: 2006 | C4: 29 | D4: 32 | E4: 32 | F4: 15 | G4: 44 | H4: 48 | I4: 9 | J4: 46 | K4: 29 | L4: 20 | M4: 59 | N4: 28 | O4: =SUM(C4:N4) -> 391 | P4: =AVERAGE(C4:N4) -> 32.583333 | Q4: 418 | R4: =S4/P4 -> 0.8286445 | S4: =SUM(Q4-O4) -> 27
A5: Cab Franc | B5: 2006 | C5: 13 | D5: 22 | E5: 20 | F5: 24 | G5: 25 | O5: =SUM(C5:N5) -> 104 | P5: =AVERAGE(C5:N5) -> 20.8 | Q5: 104 | R5: =S5/P5 -> 0 | S5: =SUM(Q5-O5) -> 0
A6: Cab Sauv | B6: 2006 | C6: 11 | D6: 13 | E6: 17 | F6: 14 | G6: 28 | H6: 24 | I6: 6 | J6: 22 | O6: =SUM(C6:N6) -> 135 | P6: =AVERAGE(C6:N6) -> 16.875 | Q6: 135 | R6: =S6/P6 -> 0 | S6: =SUM(Q6-O6) -> 0
A7: Chardonnay | B7: 2006 | C7: 22 | D7: 25 | E7: 27 | F7: 33 | G7: 48 | H7: 31 | O7: =SUM(C7:N7) -> 186 | P7: =AVERAGE(C7:N7) -> 31 | Q7: 186 | R7: =S7/P7 -> 0 | S7: =SUM(Q7-O7) -> 0
A8: Merlot | B8: 2006 | C8: 16 | D8: 16 | E8: 24 | F8: 25 | G8: 32 | H8: 29 | O8: =SUM(C8:N8) -> 142 | P8: =AVERAGE(C8:N8) -> 23.666667 | Q8: 142 | R8: =S8/P8 -> 0 | S8: =SUM(Q8-O8) -> 0
A9: Petite Verdot | B9: 2006 | C9: 13 | D9: 11 | E9: 12 | F9: 16 | O9: =SUM(C9:N9) -> 52 | P9: =AVERAGE(C9:N9) -> 13 | Q9: 52 | R9: =S9/P9 -> 0 | S9: =SUM(Q9-O9) -> 0
A10: Ameritage | B10: 2007 | C10: 7 | D10: 13 | G10: 7 | H10: 11 | I10: 16 | J10: 4 | L10: 2 | M10: 6 | N10: 0 | O10: =SUM(C10:N10) -> 66 | P10: =AVERAGE(C10:N10) -> 7.3333333 | Q10: 580 | R10: =S10/P10 -> 70.090909 | S10: =SUM(Q10-O10) -> 514
A11: Ameritage Reserve | B11: 2007 | C11: 18 | F11: 11 | G11: 32 | H11: 40 | I11: 11 | J11: 31 | K11: 32 | L11: 34 | M11: 44 | N11: 0 | O11: =SUM(C11:N11) -> 253 | P11: =AVERAGE(C11:N11) -> 25.3 | Q11: 277 | R11: =S11/P11 -> 0.9486166 | S11: =SUM(Q11-O11) -> 24
A12: Cab Franc | B12: 2007 | C12: 5 | D12: 17 | F12: 15 | G12: 22 | H12: 43 | I12: 14 | J12: 11 | O12: =SUM(C12:N12) -> 127 | P12: =AVERAGE(C12:N12) -> 18.142857 | Q12: 127 | R12: =S12/P12 -> 0 | S12: =SUM(Q12-O12) -> 0
A13: Cab Sauv | B13: 2007 | C13: 4 | D13: 9 | F13: 14 | H13: 10 | I13: 8 | J13: 3 | K13: 30 | L13: 27 | M13: 36 | N13: 40 | O13: =SUM(C13:N13) -> 181 | P13: =AVERAGE(C13:N13) -> 18.1 | Q13: 484 | R13: =S13/P13 -> 16.740331 | S13: =SUM(Q13-O13) -> 303
A14: Chardonnay | B14: 2007 | C14: 13 | D14: 18 | E14: 21 | F14: 8 | G14: 25 | H14: 50 | I14: 38 | J14: 61 | K14: 58 | L14: 43 | M14: 28 | O14: =SUM(C14:N14) -> 363 | P14: =AVERAGE(C14:N14) -> 33 | Q14: 363 | R14: =S14/P14 -> 0 | S14: =SUM(Q14-O14) -> 0
A15: LH Viognier | B15: 2007 | C15: 11 | D15: 19 | E15: 19 | F15: 24 | G15: 12 | O15: =SUM(C15:N15) -> 85 | P15: =AVERAGE(C15:N15) -> 17 | Q15: 85 | R15: =S15/P15 -> 0 | S15: =SUM(Q15-O15) -> 0
A16: Malbec | B16: 2007 | C16: 6 | D16: 17 | E16: 13 | F16: 15 | G16: 10 | O16: =SUM(C16:N16) -> 61 | P16: =AVERAGE(C16:N16) -> 12.2 | Q16: 61 | R16: =S16/P16 -> 0 | S16: =SUM(Q16-O16) -> 0
A17: Merlot | B17: 2007 | C17: 3 | D17: 2 | H17: 24 | I17: 21 | J17: 33 | K17: 27 | O17: =SUM(C17:N17) -> 110 | P17: =AVERAGE(C17:N17) -> 18.333333 | Q17: 110 | R17: =S17/P17 -> 0 | S17: =SUM(Q17-O17) -> 0
A18: Petite Verdot | B18: 2007 | C18: 3 | D18: 8 | F18: 16 | G18: 24 | H18: 38 | I18: 13 | J18: 35 | K18: 24 | L18: 23 | M18: 79 | N18: 0 | O18: =SUM(C18:N18) -> 263 | P18: =AVERAGE(C18:N18) -> 23.909091 | Q18: 319 | R18: =S18/P18 -> 2.3422053 | S18: =SUM(Q18-O18) -> 56
A19: Sauv Blanc | B19: 2007 | C19: 24 | D19: 11 | E19: 18 | F19: 33 | O19: =SUM(C19:N19) -> 86 | P19: =AVERAGE(C19:N19) -> 21.5 | Q19: 86 | R19: =S19/P19 -> 0 | S19: =SUM(Q19-O19) -> 0
A20: Viognier | B20: 2007 | C20: 29 | D20: 48 | E20: 38 | F20: 16 | O20: =SUM(C20:N20) -> 131 | P20: =AVERAGE(C20:N20) -> 32.75 | Q20: 131 | R20: =S20/P20 -> 0 | S20: =SUM(Q20-O20) -> 0
A21: Ameritage | B21: 2008 | N21: 0 | O21: =SUM(C21:N21) -> 0 | P21: =AVERAGE(C21:N21) -> 0 | Q21: 827 | R21: =S21/P21 -> #DIV/0! | S21: =SUM(Q21-O21) -> 827
A22: Ameritage Reserve | B22: 2008 | N22: 0 | O22: =SUM(C22:N22) -> 0 | P22: =AVERAGE(C22:N22) -> 0 | Q22: 342 | R22: =S22/P22 -> #DIV/0! | S22: =SUM(Q22-O22) -> 342
A23: Cab Franc | B23: 2008 | I23: 5 | J23: 30 | K23: 30 | L23: 37 | M23: 52 | N23: 21 | O23: =SUM(C23:N23) -> 175 | P23: =AVERAGE(C23:N23) -> 29.166667 | Q23: 524 | R23: =S23/P23 -> 11.965714 | S23: =SUM(Q23-O23) -> 349
A24: Cab Sauv | B24: 2008 | N24: 0 | O24: =SUM(C24:N24) -> 0 | P24: =AVERAGE(C24:N24) -> 0 | Q24: 230 | R24: =S24/P24 -> #DIV/0! | S24: =SUM(Q24-O24) -> 230
A25: Chardonnay | B25: 2008 | H25: 48 | M25: 50 | N25: 48 | O25: =SUM(C25:N25) -> 146 | P25: =AVERAGE(C25:N25) -> 48.666667 | Q25: 700 | R25: =S25/P25 -> 11.383562 | S25: =SUM(Q25-O25) -> 554
A26: LH Viognier | B26: 2008 | H26: 32 | I26: 33 | J26: 24 | K26: 23 | L26: 22 | M26: 27 | N26: 16 | O26: =SUM(C26:N26) -> 177 | P26: =AVERAGE(C26:N26) -> 25.285714 | Q26: 350 | R26: =S26/P26 -> 6.8418079 | S26: =SUM(Q26-O26) -> 173
A27: Malbec | B27: 2008 | L27: 45 | M27: 16 | N27: 17 | O27: =SUM(C27:N27) -> 78 | P27: =AVERAGE(C27:N27) -> 26 | Q27: 154 | R27: =S27/P27 -> 2.9230769 | S27: =SUM(Q27-O27) -> 76
A28: Merlot | B28: 2008 | J28: 7 | K28: 10 | L28: 30 | M28: 46 | N28: 17 | O28: =SUM(C28:N28) -> 110 | P28: =AVERAGE(C28:N28) -> 22 | Q28: 372 | R28: =S28/P28 -> 11.909091 | S28: =SUM(Q28-O28) -> 262
A29: Petite Verdot | B29: 2008 | K29: 4 | L29: 8 | M29: 2 | N29: 0 | O29: =SUM(C29:N29) -> 14 | P29: =AVERAGE(C29:N29) -> 3.5 | Q29: 247 | R29: =S29/P29 -> 66.571429 | S29: =SUM(Q29-O29) -> 233
A30: Redmund's | B30: 2008 | H30: 20 | I30: 2 | J30: 10 | K30: 7 | L30: 9 | M30: 7 | N30: 4 | O30: =SUM(C30:N30) -> 59 | P30: =AVERAGE(C30:N30) -> 8.4285714 | Q30: 180 | R30: =S30/P30 -> 14.355932 | S30: =SUM(Q30-O30) -> 121
A31: Riesling | B31: 2008 | E31: 101 | F31: 42 | G31: 53 | H31: 57 | I31: 38 | J31: 21 | K31: 36 | L31: 34 | M31: 38 | N31: 24 | O31: =SUM(C31:N31) -> 444 | P31: =AVERAGE(C31:N31) -> 44.4 | Q31: 515 | R31: =S31/P31 -> 1.5990991 | S31: =SUM(Q31-O31) -> 71
A32: Sauv Blanc | B32: 2008 | E32: 8 | G32: 41 | H32: 25 | I32: 24 | J32: 29 | K32: 24 | L32: 182 | M32: 25 | N32: 16 | O32: =SUM(C32:N32) -> 374 | P32: =AVERAGE(C32:N32) -> 41.555556 | Q32: 449 | R32: =S32/P32 -> 1.8048128 | S32: =SUM(Q32-O32) -> 75
A33: Sweet Petite | B33: 2008 | H33: 75 | I33: 10 | J33: 26 | K33: 28 | L33: 19 | M33: 36 | N33: 16 | O33: =SUM(C33:N33) -> 210 | P33: =AVERAGE(C33:N33) -> 30 | Q33: 340 | R33: =S33/P33 -> 4.3333333 | S33: =SUM(Q33-O33) -> 130
A34: Viognier | B34: 2008 | G34: 69 | H34: 64 | I34: 17 | J34: 52 | K34: 53 | L34: 45 | M34: 52 | N34: 29 | O34: =SUM(C34:N34) -> 381 | P34: =AVERAGE(C34:N34) -> 47.625 | Q34: 653 | R34: =S34/P34 -> 5.7112861 | S34: =SUM(Q34-O34) -> 272
A36: Totals | B36: 2006 | C36: =SUM(C3:C34) -> 242 | D36: =SUM(D3:D10) -> 146 | E36: =SUM(E3:E9) -> 147 | F36: =SUM(F3:F16) -> 230 | G36: =SUM(G3:G12) -> 238 | H36: =SUM(H3:H14) -> 286 | I36: =SUM(I3:I9) -> 15 | J36: =SUM(J3:J9) -> 68 | K36: =SUM(K3:K9) -> 29 | L36: =SUM(L3:L9) -> 20 | M36: =SUM(M3:M9) -> 59 | N36: =SUM(N3:N9) -> 28 | O36: =SUM(C36:N36) -> 1508 | P36: =O36/4 -> 377 | Q36: =SUM(Q3:Q9) -> 1097 | R36: =Q36/P36 -> 2.9098143
B37: 2007 | C37: =SUM(C10:C20) -> 123 | D37: =SUM(D10:D20) -> 162 | E37: =SUM(E10:E20) -> 109 | F37: =SUM(F10:F20) -> 152 | G37: =SUM(G10:G20) -> 132 | H37: =SUM(H10:H20) -> 216 | I37: =SUM(I10:I20) -> 121 | J37: =SUM(J10:J20) -> 178 | ... N37: =SUM(N10:N20) -> 40 | O37: =SUM(C37:N37) -> 1726 | P37: =O37/4 -> 431.5 | Q37: =SUM(Q12:Q34) -> 7649 | R37: =Q37/P37 -> 17.726535
B38: 2008 | C38: =SUM(C31:C34) -> 0 | D38: =SUM(D31:D34) -> 0 | E38: =SUM(E31:E34) -> 109 | F38: =SUM(F31:F34) -> 42 | G38: =SUM(G31:G34) -> 163 | H38: =SUM(H31:H34) -> 221 | I38: =SUM(I31:I34) -> 89 | J38: =SUM(J31:J34) -> 128 | ... N38: =SUM(N31:N34) -> 85 | O38: =SUM(C38:N38) -> 1409 | P38: =O38/4 -> 352.25 | Q38: =SUM(Q31:Q34) -> 1957 | R38: =Q38/P38 -> 5.5557133
A40: Reds | C40: =SUM(C3:C6,C8:C13, C16:C18) -> 143 | D40: =SUM(D3:D6,D8:D13, D16:D18) -> 174 | E40: =SUM(E3:E6,E8:E13, E16:E18) -> 133 | F40: =SUM(F3:F6,F8:F13, F16:F18) -> 181 | G40: =SUM(G3:G6,G8:G13, G16:G18) -> 224 | H40: =SUM(H3:H6,H8:H13, H16:H18) -> 267 | I40: =SUM(I3:I6,I8:I13, I16:I18) -> 98 | J40: =SUM(J3:J6,J8:J13, J16:J18) -> 185 | ... N40: =SUM(N3:N6,N8:N13, N16:N18) -> 68 | O40: =SUM(C40:N40) -> 1945 | P40: =O40/4 -> 486.25 | Q40: =SUM(Q3:Q6, Q8:Q13, Q16:Q18) -> 2869 | R40: =Q40/P40 -> 5.9002571
A41: Whites | C41: =SUM(C7, C14:C15, C19:C34) -> 99 | D41: =SUM(D7, D14:D15, D19:D34) -> 121 | E41: =SUM(E7, E14:E15, E19:E34) -> 232 | F41: =SUM(F7, F14:F15, F19:F34) -> 156 | G41: =SUM(G7, G14:G15, G19:G34) -> 248 | H41: =SUM(H7, H14:H15, H19:H34) -> 402 | I41: =SUM(I7, I14:I15, I19:I34) -> 167 | J41: =SUM(J7, J14:J15, J19:J34) -> 260 | ... N41: =SUM(N7, N14:N15, N19:N34) -> 208 | O41: =SUM(C41:N41) -> 3019 | P41: =O41/4 -> 754.75 | Q41: =SUM(Q7,Q14:Q15, Q19:Q34) -> 6734 | R41: =Q41/P41 -> 8.9221597

Sheet 2010
C1: CASES MOVED PER MONTH
A2: Year | C2: Wine | D2: 2009 Monthly Avg. | E2: 2010 BOY Inventory | F2: Jan | G2: Feb | H2: Mar | I2: Apr | J2: May | K2: Jun | L2: Jul | M2: Aug | N2: Sep | O2: Oct | P2: Nov | Q2: Dec | R2: Totals | S2: 2010 Monthly Avg. | T2: Months Left | U2: Remaining Inventory
A3: 2006 | C3: Ameritage | D3: 32.583333 | E3: 27 | F3: 0 | Q3: 0 | R3: =SUM(F3:Q3) -> 0 | S3: =AVERAGE(F3:Q3) -> 0 | T3: =U3/S3 -> #DIV/0! | U3: 0
A5: 2007 | C5: Ameritage | D5: 7.3333333 | E5: 514 | F5: 12 | G5: 10 | H5: 15 | I5: 4 | J5: 16 | K5: 16 | L5: 9 | M5: 2 | N5: 13 | O5: 0 | P5: 13 | Q5: 5 | R5: =SUM(F5:Q5) -> 115 | S5: =AVERAGE(F5:Q5) -> 9.5833333 | T5: =U5/S5 -> 41.634783 | U5: =SUM(E5-R5) -> 399
A6: 2007 | C6: Ameritage Reserve | D6: 25.3 | E6: 0 | F6: 0 | R6: =SUM(F6:Q6) -> 0 | S6: =AVERAGE(F6:Q6) -> 0 | T6: 0 | U6: =SUM(E6-R6) -> 0
A7: 2007 | C7: Cab Sauv | D7: 18.1 | E7: 303 | F7: 3 | G7: 13 | H7: 37 | I7: 13 | J7: 33 | K7: 22 | L7: 26 | M7: 30 | N7: 50 | O7: 37 | P7: 0 | Q7: 0 | R7: =SUM(F7:Q7) -> 264 | S7: =AVERAGE(F7:Q7) -> 22 | T7: =U7/S7 -> 0 | U7: 0
A8: 2007 | C8: Petite Verdot | D8: 23.909091 | E8: 56 | F8: 15 | G8: 20 | H8: 0 | R8: =SUM(F8:Q8) -> 35 | S8: =AVERAGE(F8:Q8) -> 11.666667 | T8: =U8/S8 -> 0 | U8: 0
A9: 2007 | C9: Vin De Sol | E9: 259 | K9: 27 | L9: 12 | M9: 16 | N9: 9 | O9: 24 | P9: 31 | Q9: 11 | R9: =SUM(F9:Q9) -> 130 | S9: =AVERAGE(F9:Q9) -> 18.571429 | T9: =U9/S9 -> 6.9461538 | U9: =SUM(E9-R9) -> 129
N10: 0
A11: 2008 | C11: Ameritage | D11: 0 | E11: 827 | F11: 3 | G11: 24 | H11: 80 | I11: 40 | J11: 29 | K11: 43 | L11: 65 | M11: 65 | N11: 41 | O11: 62 | P11: 66 | Q11: 41 | R11: =SUM(F11:Q11) -> 559 | S11: =AVERAGE(F11:Q11) -> 46.583333 | T11: =U11/S11 -> 5.7531306 | U11: =SUM(E11-R11) -> 268
A12: 2008 | C12: Ameritage Reserve | D12: 0 | E12: 342 | F12: 47 | G12: 10 | H12: 31 | I12: 24 | J12: 29 | K12: 22 | L12: 33 | M12: 24 | N12: 55 | O12: 21 | P12: 32 | Q12: 14 | R12: =SUM(F12:Q12) -> 342 | S12: =AVERAGE(F12:Q12) -> 28.5 | T12: =U12/S12 -> 0 | U12: =SUM(E12-R12) -> 0
A13: 2008 | C13: Cab Franc | D13: 29.166667 | E13: 349 | F13: 39 | G13: 43 | H13: 33 | I13: 17 | J13: 45 | K13: 8 | L13: 22 | M13: 37 | N13: 25 | O13: 34 | P13: 29 | Q13: 11 | R13: =SUM(F13:Q13) -> 343 | S13: =AVERAGE(F13:Q13) -> 28.583333 | T13: =U13/S13 -> 0.20991254 | U13: =SUM(E13-R13) -> 6
A14: 2008 | C14: Cab Sauv | D14: 0 | E14: 206 | F14: 0 | G14: 0 | H14: 0 | I14: 3 | J14: 11 | K14: 0 | L14: 0 | M14: 0 | N14: 0 | O14: 0 | P14: 1 | Q14: 18 | R14: =SUM(F14:Q14) -> 33 | S14: =AVERAGE(F14:Q14) -> 2.75 | T14: =U14/S14 -> 62.909091 | U14: =SUM(E14-R14) -> 173
A15: 2008 | C15: Chardonnay | D15: 48.666667 | E15: 554 | F15: 75 | G15: 0 | H15: 54 | I15: 38 | J15: 55 | K15: 46 | L15: 122 | M15: 0 | N15: 54 | O15: 49 | P15: 38 | Q15: 23 | R15: =SUM(F15:Q15) -> 554 | S15: =AVERAGE(F15:Q15) -> 46.166667 | T15: =U15/S15 -> 0 | U15: =SUM(E15-R15) -> 0
A16: 2008 | C16: LH Viognier | D16: 25.285714 | E16: 173 | F16: 7 | G16: 9 | H16: 18 | I16: 12 | J16: 19 | K16: 19 | L16: 20 | M16: 17 | N16: 21 | O16: 20 | P16: 0 | R16: =SUM(F16:Q16) -> 162 | S16: =AVERAGE(F16:Q16) -> 14.727273 | T16: =U16/S16 -> 0 | U16: 0
A17: 2008 | C17: Malbec | D17: 26 | E17: 76 | F17: 6 | G17: 8 | H17: 0 | I17: 0 | J17: 0 | K17: 0 | L17: 0 | M17: 0 | N17: 0 | R17: =SUM(F17:Q17) -> 14 | S17: =AVERAGE(F17:Q17) -> 1.5555556 | T17: =U17/S17 -> 0 | U17: 0
A18: 2008 | C18: Merlot | D18: 22 | E18: 262 | F18: 10 | G18: 13 | H18: 83 | I18: -38 | J18: 27 | K18: 17 | L18: 27 | M18: 22 | N18: 25 | O18: 30 | P18: 18 | Q18: 8 | R18: =SUM(F18:Q18) -> 242 | S18: =AVERAGE(F18:Q18) -> 20.166667 | T18: =U18/S18 -> 0.99173554 | U18: =SUM(E18-R18) -> 20
A19: 2008 | C19: Petite Verdot | D19: 3.5 | E19: 233 | F19: 6 | G19: 0 | H19: 10 | I19: 15 | J19: 17 | K19: 21 | L19: 13 | M19: 20 | N19: 18 | O19: 34 | P19: 18 | Q19: 14 | R19: =SUM(F19:Q19) -> 186 | S19: =AVERAGE(F19:Q19) -> 15.5 | T19: =U19/S19 -> 3.0322581 | U19: =SUM(E19-R19) -> 47
A20: 2008 | C20: Redmund's | D20: 8.4285714 | E20: 121 | F20: 1 | G20: 1 | H20: 0 | I20: 1 | J20: 0 | K20: 0 | L20: 0 | M20: 0 | N20: 0 | R20: =SUM(F20:Q20) -> 3 | S20: =AVERAGE(F20:Q20) -> 0.33333333 | T20: =U20/S20 -> 0 | U20: 0
A21: 2008 | C21: Riesling | D21: 44.4 | E21: 71 | F21: 12 | G21: 17 | H21: 32 | I21: 0 | M21: 0 | N21: 0 | R21: =SUM(F21:Q21) -> 61 | S21: =AVERAGE(F21:Q21) -> 10.166667 | T21: =U21/S21 -> 0 | U21: 0
A22: 2008 | C22: Sauv Blanc | D22: 41.555556 | E22: 75 | F22: 10 | G22: 9 | H22: 18 | I22: 17 | J22: 0 | K22: 0 | M22: 0 | N22: 0 | R22: =SUM(F22:Q22) -> 54 | S22: =AVERAGE(F22:Q22) -> 6.75 | T22: =U22/S22 -> 0 | U22: 0
A23: 2008 | C23: Sweet Petit | D23: 30 | E23: 130 | F23: 9 | G23: 6 | H23: 21 | I23: 15 | J23: 36 | K23: 28 | M23: 0 | N23: 0 | R23: =SUM(F23:Q23) -> 115 | S23: =AVERAGE(F23:Q23) -> 14.375 | T23: =U23/S23 -> 0 | U23: 0
A24: 2008 | C24: Viognier | D24: 47.625 | E24: 272 | F24: 21 | G24: 20 | H24: 39 | I24: 33 | J24: 45 | K24: 24 | L24: 43 | M24: 0 | N24: 0 | R24: =SUM(F24:Q24) -> 225 | S24: =AVERAGE(F24:Q24) -> 25 | T24: =U24/S24 -> 0 | U24: 0
M25: 0
A26: 2009 | C26: Ameritage | D26: 347 | E26: 0 | F26: 0 | M26: 0 | N26: 0 | R26: =SUM(F26:Q26) -> 0 | S26: =AVERAGE(F26:Q26) -> 0 | T26: =U26/S26 -> #DIV/0! | U26: =SUM(E26-R26) -> 0
A27: 2009 | C27: Ameritage Reserve | D27: 455 | E27: 0 | F27: 0 | M27: 0 | N27: 0 | R27: =SUM(F27:Q27) -> 0 | S27: =AVERAGE(F27:Q27) -> 0 | T27: =U27/S27 -> #DIV/0! | U27: =SUM(E27-R27) -> 0
A28: 2009 | C28: Cab Franc | E28: 714 | F28: 0 | M28: 20 | N28: 0 | O28: 13 | P28: 10 | Q28: 0 | R28: =SUM(F28:Q28) -> 43 | S28: =AVERAGE(F28:Q28) -> 7.1666667 | T28: =U28/S28 -> 93.627907 | U28: =SUM(E28-R28) -> 671
A29: 2009 | C29: Cab Sauv | D29: 242 | E29: 0 | F29: 0 | M29: 0 | N29: 0 | R29: =SUM(F29:Q29) -> 0 | S29: =AVERAGE(F29:Q29) -> 0 | T29: =U29/S29 -> #DIV/0! | U29: =SUM(E29-R29) -> 0
A30: 2009 | C30: Chardonnay | E30: 556 | F30: 0 | M30: 0 | N30: 18 | O30: 0 | P30: 52 | R30: =SUM(F30:Q30) -> 70 | S30: =AVERAGE(F30:Q30) -> 14 | T30: =U30/S30 -> 34.714286 | U30: =SUM(E30-R30) -> 486
A31: 2009 | C31: LH Viognier | E31: 0 | F31: 0 | M31: 0 | N31: 0 | R31: =SUM(F31:Q31) -> 0 | S31: =AVERAGE(F31:Q31) -> 0 | T31: =U31/S31 -> #DIV/0! | U31: =SUM(E31-R31) -> 0
A32: 2009 | C32: Malbec | E32: 250 | F32: 0 | M32: 3 | N32: 19 | O32: 73 | P32: 21 | Q32: 12 | R32: =SUM(F32:Q32) -> 128 | S32: =AVERAGE(F32:Q32) -> 21.333333 | T32: =U32/S32 -> 5.71875 | U32: =SUM(E32-R32) -> 122
A33: 2009 | C33: Merlot | E33: 457 | F33: 0 | M33: 0 | N33: 0 | O33: 0 | Q33: 2 | R33: =SUM(F33:Q33) -> 2 | S33: =AVERAGE(F33:Q33) -> 0.4 | T33: =U33/S33 -> 1137.5 | U33: =SUM(E33-R33) -> 455
A34: 2009 | C34: Petite Verdot | E34: 222 | F34: 0 | M34: 0 | N34: 0 | O34: 5 | P34: 5 | Q34: 3 | R34: =SUM(F34:Q34) -> 13 | S34: =AVERAGE(F34:Q34) -> 2.1666667 | T34: =U34/S34 -> 96.461538 | U34: =SUM(E34-R34) -> 209
A35: 2009 | C35: Redmund's | E35: 251 | F35: 0 | K35: 10 | L35: 6 | M35: 20 | N35: 10 | O35: 8 | P35: 31 | Q35: 0 | R35: =SUM(F35:Q35) -> 85 | S35: =AVERAGE(F35:Q35) -> 10.625 | T35: =U35/S35 -> 15.623529 | U35: =SUM(E35-R35) -> 166
A36: 2009 | C36: Riesling | D36: 44.4 | E36: 415 | F36: 0 | G36: 0 | H36: 0 | I36: 40 | J36: 55 | K36: 61 | L36: 48 | M36: 105 | N36: 56 | O36: 0 | R36: =SUM(F36:Q36) -> 365 | S36: =AVERAGE(F36:Q36) -> 36.5 | T36: =U36/S36 -> 0 | U36: 0
A37: 2009 | C37: Harrys Tap Room | F37: 0 | M37: 0 | N37: 0 | R37: 60 | S37: =AVERAGE(F37:Q37) -> 0 | T37: 0 | U37: 0
A38: 2009 | C38: Sweet Petit | E38: 0 | F38: 0 | M38: 0 | N38: 0 | R38: =SUM(F38:Q38) -> 0 | S38: =AVERAGE(F38:Q38) -> 0 | T38: =U38/S38 -> #DIV/0! | U38: =SUM(E38-R38) -> 0
A39: 2009 | C39: Viognier | E39: 596 | F39: 0 | L39: 3 | M39: 0 | N39: 58 | O39: 60 | P39: 50 | Q39: 28 | R39: =SUM(F39:Q39) -> 199 | S39: =AVERAGE(F39:Q39) -> 28.428571 | T39: =U39/S39 -> 13.964824 | U39: =SUM(E39-R39) -> 397
A40: 2009 | C40: LH Petit Manseng | E40: 287 | L40: 0 | M40: 25 | N40: 9 | O40: 11 | P40: 14 | Q40: 12 | R40: =SUM(F40:Q40) -> 71 | S40: =AVERAGE(F40:Q40) -> 11.833333 | T40: =U40/S40 -> 18.253521 | U40: =SUM(E40-R40) -> 216
A41: 2009 | C41: Petit Manseng | D41: n/a | E41: 323 | F41: 0 | G41: 0 | H41: 0 | I41: 25 | J41: 40 | K41: 76 | L41: 52 | M41: 0 | N41: 40 | O41: 26 | Q41: 0 | R41: =SUM(F41:Q41) -> 259 | S41: =AVERAGE(F41:Q41) -> 23.545455 | T41: =U41/S41 -> 0 | U41: 0
...

Sheet hp

Sheet 2013
J1: Bulk wines | K1: 2013 vintage
D2: Shiners | E2: 56 ‘12 pv | J2: Red | K2: 9200 | L2: gal | M2: including 1200 gal of reds stored at VH
D3: at VHCW | E3: 84 ‘11 cf | J3: white | K3: 11087 | L3: gal | M3: including 2300 gal of delaney made at PC
E4: 68 ‘10 ameritage
B7: CASES MOVED PER MONTH
A8: ABC # | B8: Year | C8: Wine | D8: 2011 Monthly Avg. | E8: 2013 BOY Inventory | F8: Jan | G8: Feb | H8: Mar | I8: Apr | J8: May | K8: Jun | L8: Jul | M8: Aug | N8: Sep | O8: Oct | P8: Nov | Q8: Dec | R8: Totals | S8: 2012 Monthly Avg. | T8: Months Left | U8: Remaining Inventory | X8: Tasting Room | Y8: Totals
B9: 2009 | C9: Ameritage Reserve | D9: 22 | E9: 21 | F9: 21 | G9: 0 | R9: =SUM(F9:Q9) -> 21 | S9: =AVERAGE(F9:Q9) -> 10.5 | T9: =U9/S9 -> 0 | U9: =SUM(E9-R9) -> 0
B10: 2009 | C10: Cab Franc | D10: 29 | E10: 118 | F10: 23 | G10: 17 | H10: 14 | I10: 34 | J10: 28 | K10: 2 | R10: =SUM(F10:Q10) -> 118 | S10: =AVERAGE(F10:Q10) -> 19.666667 | T10: =U10/S10 -> 0 | U10: =SUM(E10-R10) -> 0
B11: 2009 | C11: Merlot | D11: 16 | E11: 13 | F11: 13 | G11: 0 | R11: =SUM(F11:Q11) -> 13 | S11: =AVERAGE(F11:Q11) -> 6.5 | T11: =U11/S11 -> 0 | U11: =SUM(E11-R11) -> 0
A13: 57630 | B13: 2010 | C13: Chardonnay | D13: 38 | E13: 255 | F13: 25 | G13: 29 | H13: 26 | I13: 38 | J13: 35 | K13: 35 | L13: 48 | M13: 19 | R13: =SUM(F13:Q13) -> 255 | S13: =AVERAGE(F13:Q13) -> 31.875 | T13: =U13/S13 -> 0 | U13: =SUM(E13-R13) -> 0
A14: 65560 | B14: 2010 | C14: Hen's Night | D14: 30 | E14: 84 | F14: 11 | G14: 10 | H14: 9 | I14: 17 | J14: 21 | R14: =SUM(F14:Q14) -> 68 | S14: =AVERAGE(F14:Q14) -> 13.6 | T14: =U14/S14 -> 0 | U14: 0
A15: 57632 | B15: 2010 | C15: Viognier | D15: 31 | E15: 151 | F15: 19 | G15: 18 | H15: 16 | I15: 62 | J15: 36 | R15: =SUM(F15:Q15) -> 151 | S15: =AVERAGE(F15:Q15) -> 30.2 | T15: =U15/S15 -> 0 | U15: =SUM(E15-R15) -> 0
A16: 22382 | B16: 2010 | C16: Cab Franc | D16: 29 | E16: 283 | F16: 13 | G16: 6 | H16: 4 | I16: 0 | J16: 0 | K16: 30 | L16: 34 | M16: 28 | N16: 44 | O16: 42 | P16: 24 | Q16: 22 | R16: =SUM(F16:Q16) -> 247 | S16: =AVERAGE(F16:Q16) -> 20.583333 | T16: =U16/S16 -> 1.7489879 | U16: =SUM(E16-R16) -> 36 | X16: 3 | Y16: =U16+X16 -> 39
A17: 22834 | B17: 2010 | C17: Merlot | D17: 16 | E17: 308 | F17: 2 | G17: 12 | H17: 12 | I17: 6 | J17: 30 | K17: 14 | L17: 20 | M17: 3 | N17: 19 | O17: 33 | P17: 22 | Q17: 59 | R17: =SUM(F17:Q17) -> 232 | S17: =AVERAGE(F17:Q17) -> 19.333333 | T17: =U17/S17 -> 3.9310345 | U17: =SUM(E17-R17) -> 76 | X17: 4 | Y17: =U17+X17 -> 80
A18: 28361 | B18: 2010 | C18: Cab Sauv | D18: 25 | E18: 238 | F18: 16 | G18: 15 | H18: 18 | I18: 22 | J18: 25 | K18: 18 | L18: 21 | M18: 19 | N18: 30 | O18: 35 | P18: 13 | Q18: 6 | R18: =SUM(F18:Q18) -> 238 | S18: =AVERAGE(F18:Q18) -> 19.833333 | T18: =U18/S18 -> 0 | U18: =SUM(E18-R18) -> 0 | Y18: =U18+X18 -> 0
A19: 27736 | B19: 2010 | C19: Petite Verdot | D19: 21 | E19: 301 | F19: 23 | G19: 22 | H19: 15 | I19: 15 | J19: 45 | K19: 25 | L19: 27 | M19: 23 | N19: 38 | O19: 39 | P19: 20 | Q19: 9 | R19: =SUM(F19:Q19) -> 301 | S19: =AVERAGE(F19:Q19) -> 25.083333 | T19: =U19/S19 -> 0 | U19: =SUM(E19-R19) -> 0 | Y19: =U19+X19 -> 0
A20: 18004 | B20: 2010 | C20: Malbec | D20: 12 | E20: 168 | F20: 16 | G20: 8 | H20: 7 | I20: 12 | J20: 11 | K20: 6 | L20: 12 | M20: 16 | N20: 13 | O20: 19 | P20: 8 | Q20: 8 | R20: =SUM(F20:Q20) -> 136 | S20: =AVERAGE(F20:Q20) -> 11.333333 | T20: =U20/S20 -> 2.8235294 | U20: =SUM(E20-R20) -> 32 | X20: 3 | Y20: =U20+X20 -> 35
A21: 34641 | B21: 2010 | C21: Ameritage Res | D21: 22 | E21: 573 | F21: 8 | G21: 24 | H21: 27 | I21: 20 | J21: 21 | K21: 20 | L21: 27 | M21: 21 | N21: 34 | O21: 53 | P21: 16 | Q21: 24 | R21: =SUM(F21:Q21) -> 295 | S21: =AVERAGE(F21:Q21) -> 24.583333 | T21: =U21/S21 -> 11.308475 | U21: =SUM(E21-R21) -> 278 | X21: 4 | Y21: =U21+X21 -> 282
A22: 22921 | B22: 2010 | C22: Ameritage | D22: 37 | E22: 396 | F22: 43 | G22: 21 | H22: 9 | I22: 24 | J22: 46 | K22: 0 | L22: 7 | M22: 10 | N22: 26 | O22: 47 | P22: 35 | Q22: 46 | R22: =SUM(F22:Q22) -> 314 | S22: =AVERAGE(F22:Q22) -> 26.166667 | T22: =U22/S22 -> 3.133758 | U22: =SUM(E22-R22) -> 82 | X22: 2 | Y22: =U22+X22 -> 84
A23: 38269 | B23: 2010 | C23: LH Petit Manseng | D23: 13 | E23: 210 | F23: 20 | G23: 6 | H23: 6 | I23: 14 | J23: 13 | K23: 13 | L23: 15 | M23: 3 | N23: 17 | O23: 16 | P23: 14 | Q23: 4 | R23: =SUM(F23:Q23) -> 141 | S23: =AVERAGE(F23:Q23) -> 11.75 | T23: =U23/S23 -> 5.8723404 | U23: =SUM(E23-R23) -> 69 | X23: 3 | Y23: =U23+X23 -> 72
F24: 1 | Y24: =U24+X24 -> 0
A25: 11198 | B25: 2011 | C25: Petit Manseng | D25: 25 | E25: 281 | F25: 46 | G25: 25 | H25: 210 | R25: =SUM(F25:Q25) -> 281 | S25: =AVERAGE(F25:Q25) -> 93.666667 | T25: =U25/S25 -> 0 | U25: =SUM(E25-R25) -> 0 | Y25: =U25+X25 -> 0
A26: 57630 | B26: 2011 | C26: Chardonnay | D26: 38 | E26: 535 | F26: 1 | G26: 0 | H26: 0 | I26: 4 | J26: 0 | K26: 0 | L26: 0 | M26: 0 | N26: 22 | O26: 24 | P26: 0 | Q26: 60 | R26: =SUM(F26:Q26) -> 111 | S26: =AVERAGE(F26:Q26) -> 9.25 | T26: =U26/S26 -> 45.837838 | U26: =SUM(E26-R26) -> 424 | V26: 65 | W26: shiners | X26: 6 | Y26: =U26+X26 -> 430
A27: 57632 | B27: 2011 | C27: Viognier | D27: 31 | E27: 487 | F27: 1 | G27: 5 | H27: 3 | I27: 12 | J27: 18 | K27: 29 | L27: 41 | M27: 36 | N27: 143 | O27: 107 | P27: 0 | Q27: 0 | R27: =SUM(F27:Q27) -> 395 | S27: =AVERAGE(F27:Q27) -> 32.916667 | T27: =U27/S27 -> 2.7949367 | U27: =SUM(E27-R27) -> 92 | Y27: =U27+X27 -> 92
A28: 57631 | B28: 2011 | C28: Riesling | D28: 29 | E28: 147 | F28: 19 | G28: 0 | H28: 128 | R28: =SUM(F28:Q28) -> 147 | S28: =AVERAGE(F28:Q28) -> 49 | T28: =U28/S28 -> 0 | U28: =SUM(E28-R28) -> 0 | V28: 128 | W28: used | Y28: =U28+X28 -> 0
A29: 22384 | B29: 2011 | C29: Merlot | D29: 16 | E29: 243 | F29: 2 | G29: 0 | H29: 0 | I29: 0 | J29: 0 | K29: 0 | L29: 0 | M29: 0 | N29: 0 | O29: 0 | R29: =SUM(F29:Q29) -> 2 | S29: =AVERAGE(F29:Q29) -> 0.2 | T29: =U29/S29 -> 1205 | U29: =SUM(E29-R29) -> 241 | Y29: =U29+X29 -> 241
A30: 22382 | B30: 2011 | C30: Cab Franc | D30: 29 | E30: 179 | F30: 1 | G30: 0 | H30: 0 | I30: 0 | J30: 0 | K30: 0 | L30: 0 | M30: 0 | N30: 0 | O30: 0 | R30: =SUM(F30:Q30) -> 1 | S30: =AVERAGE(F30:Q30) -> 0.1 | T30: =U30/S30 -> 1780 | U30: =SUM(E30-R30) -> 178 | Y30: =U30+X30 -> 178
A31: 28361 | B31: 2011 | C31: Cab Sauv | D31: 25 | E31: 202 | F31: 5 | G31: 0 | H31: 3 | I31: 1 | J31: 3 | K31: 0 | L31: 0 | M31: 0 | N31: 0 | O31: 0 | Q31: 16 | R31: =SUM(F31:Q31) -> 28 | S31: =AVERAGE(F31:Q31) -> 2.5454545 | T31: =U31/S31 -> 68.357143 | U31: =SUM(E31-R31) -> 174 | X31: 1 | Y31: =U31+X31 -> 175
A32: 27736 | B32: 2011 | C32: Petit Verdot | D32: 21 | E32: 171 | F32: 2 | G32: 6 | H32: 0 | I32: 0 | J32: 0 | K32: 0 | L32: 0 | M32: 0 | N32: 0 | O32: 0 | Q32: 10 | R32: =SUM(F32:Q32) -> 18 | S32: =AVERAGE(F32:Q32) -> 1.6363636 | T32: =U32/S32 -> 93.5 | U32: =SUM(E32-R32) -> 153 | X32: 4 | Y32: =U32+X32 -> 157
A33: 22921 | B33: 2011 | C33: Ameritage | D33: 37 | E33: 344 | F33: 1 | G33: 0 | H33: 11 | I33: 0 | J33: 0 | K33: 0 | L33: 0 | M33: 4 | N33: 0 | O33: 0 | R33: =SUM(F33:Q33) -> 16 | S33: =AVERAGE(F33:Q33) -> 1.6 | T33: =U33/S33 -> 205 | U33: =SUM(E33-R33) -> 328 | Y33: =U33+X33 -> 328
A34: 26415 | B34: 2011 | C34: LH Tram | D34: 13 | E34: 359 | F34: 1 | G34: 4 | H34: 0 | I34: 0 | J34: 6 | K34: 14 | L34: 11 | M34: 13 | N34: 15 | O34: 16 | P34: 9 | Q34: 7 | R34: =SUM(F34:Q34) -> 96 | S34: =AVERAGE(F34:Q34) -> 8 | T34: =U34/S34 -> 32.875 | U34: =SUM(E34-R34) -> 263 | X34: 3 | Y34: =U34+X34 -> 266
Y35: =U35+X35 -> 0
A36: 57631 | B36: 2012 | C36: Riesling | E36: 547 | G36: 1 | H36: 89 | I36: 54 | J36: 64 | K36: 46 | L36: 72 | M36: 53 | N36: 66 | O36: 68 | P36: 34 | R36: =SUM(F36:Q36) -> 547 | S36: =AVERAGE(F36:Q36) -> 54.7 | T36: =U36/S36 -> 0 | U36: =SUM(E36-R36) -> 0 | Y36: =U36+X36 -> 0
A37: 11198 | B37: 2012 | C37: Petite Manseng | E37: 332 | I37: 37 | J37: 29 | K37: 27 | L37: 32 | M37: 30 | N37: 33 | O37: 40 | P37: 21 | Q37: 13 | R37: =SUM(F37:Q37) -> 262 | S37: =AVERAGE(F37:Q37) -> 29.111111 | T37: =U37/S37 -> 2.4045802 | U37: =SUM(E37-R37) -> 70 | X37: 4 | Y37: =U37+X37 -> 74
A38: 57632 | B38: 2012 | C38: Viognier | E38: 278 | M38: 3 | N38: 0 | O38: 0 | R38: =SUM(F38:Q38) -> 3 | S38: =AVERAGE(F38:Q38) -> 1 | T38: =U38/S38 -> 275 | U38: =SUM(E38-R38) -> 275 | X38: 4 | Y38: =U38+X38 -> 279
A39: 57630 | B39: 2012 | C39: Chardonnay | E39: 334 | M39: 1 | N39: 0 | O39: 0 | R39: =SUM(F39:Q39) -> 1 | S39: =AVERAGE(F39:Q39) -> 0.33333333 | T39: =U39/S39 -> 999 | U39: =SUM(E39-R39) -> 333 | V39: 24 | W39: shiners | Y39: =U39+X39 -> 333
A40: 22384 | B40: 2012 | C40: Merlot | E40: 395 | M40: 0 | N40: 0 | O40: 0 | R40: =SUM(F40:Q40) -> 0 | S40: =AVERAGE(F40:Q40) -> 0 | T40: =U40/S40 -> #DIV/0! | U40: =SUM(E40-R40) -> 395 | X40: 1 | Y40: =U40+X40 -> 396
A41: 22382 | B41: 2012 | C41: Cab Franc | E41: 449 | M41: 0 | N41: 0 | O41: 0 | R41: =SUM(F41:Q41) -> 0 | S41: =AVERAGE(F41:Q41) -> 0 | T41: =U41/S41 -> #DIV/0! | U41: =SUM(E41-R41) -> 449 | Y41: =U41+X41 -> 449
A42: 27736 | B42: 2012 | C42: Petit Verdot | E42: 392 | M42: 0 | N42: 0 | O42: 0 | R42: =SUM(F42:Q42) -> 0 | S42: =AVERAGE(F42:Q42) -> 0 | T42: =U42/S42 -> #DIV/0! | U42: =SUM(E42-R42) -> 392 | X42: 1 | Y42: =U42+X42 -> 393
A43: 28361 | B43: 2012 | C43: Cab Sauv | E43: 497 | R43: =SUM(F43:Q43) -> 0 | S43: =AVERAGE(F43:Q43) -> #DIV/0! | T43: =U43/S43 -> #DIV/0! | U43: =SUM(E43-R43) -> 497 | X43: 1 | Y43: =U43+X43 -> 498
...

Sheet 2011
A5: CASES MOVED PER MONTH
A6: Year | C6: Wine | D6: 2011 Monthly Avg. | E6: 2012 BOY Inventory | F6: Jan | G6: Feb | H6: Mar | I6: Apr | J6: May | K6: Jun | L6: Jul | M6: Aug | N6: Sep | O6: Oct | P6: Nov | Q6: Dec | R6: Totals | S6: 2012 Monthly Avg. | T6: Months Left | U6: Remaining Inventory
A7: 2009 | C7: Ameritage Reserve | D7: 22 | E7: 21 | F7: 21 | G7: 0 | R7: =SUM(F7:Q7) -> 21 | S7: =AVERAGE(F7:Q7) -> 10.5 | T7: =U7/S7 -> 0 | U7: =SUM(E7-R7) -> 0
A8: 2009 | C8: Cab Franc | D8: 29 | E8: 118 | F8: 23 | G8: 17 | H8: 14 | I8: 34 | R8: =SUM(F8:Q8) -> 88 | S8: =AVERAGE(F8:Q8) -> 22 | T8: =U8/S8 -> 1.3636364 | U8: =SUM(E8-R8) -> 30
A9: 2009 | C9: Merlot | D9: 16 | E9: 13 | F9: 13 | G9: 0 | R9: =SUM(F9:Q9) -> 13 | S9: =AVERAGE(F9:Q9) -> 6.5 | T9: =U9/S9 -> 0 | U9: =SUM(E9-R9) -> 0
A11: 2010 | C11: Chardonnay | D11: 38 | E11: 255 | F11: 25 | G11: 29 | H11: 26 | I11: 38 | R11: =SUM(F11:Q11) -> 118 | S11: =AVERAGE(F11:Q11) -> 29.5 | T11: =U11/S11 -> 4.6440678 | U11: =SUM(E11-R11) -> 137
A12: 2010 | C12: Hen's Night | D12: 30 | E12: 84 | F12: 11 | G12: 10 | H12: 9 | I12: 17 | R12: =SUM(F12:Q12) -> 47 | S12: =AVERAGE(F12:Q12) -> 11.75 | T12: =U12/S12 -> 3.1489362 | U12: =SUM(E12-R12) -> 37 | V12: 3
A13: 2010 | C13: Viognier | D13: 31 | E13: 151 | F13: 19 | G13: 18 | H13: 16 | I13: 62 | R13: =SUM(F13:Q13) -> 115 | S13: =AVERAGE(F13:Q13) -> 28.75 | T13: =U13/S13 -> 1.2521739 | U13: =SUM(E13-R13) -> 36
A14: 2010 | C14: Cab Franc | D14: 29 | E14: 283 | F14: 13 | G14: 6 | H14: 4 | I14: 0 | R14: =SUM(F14:Q14) -> 23 | S14: =AVERAGE(F14:Q14) -> 5.75 | T14: =U14/S14 -> 45.217391 | U14: =SUM(E14-R14) -> 260
A15: 2010 | C15: Merlot | D15: 16 | E15: 308 | F15: 2 | G15: 12 | H15: 12 | I15: 6 | R15: =SUM(F15:Q15) -> 32 | S15: =AVERAGE(F15:Q15) -> 8 | T15: =U15/S15 -> 34.5 | U15: =SUM(E15-R15) -> 276
A16: 2010 | C16: Cab Sauv | D16: 25 | E16: 238 | F16: 16 | G16: 15 | H16: 18 | I16: 22 | R16: =SUM(F16:Q16) -> 71 | S16: =AVERAGE(F16:Q16) -> 17.75 | T16: =U16/S16 -> 9.4084507 | U16: =SUM(E16-R16) -> 167
A17: 2010 | C17: Petite Verdot | D17: 21 | E17: 301 | F17: 23 | G17: 22 | H17: 15 | I17: 15 | R17: =SUM(F17:Q17) -> 75 | S17: =AVERAGE(F17:Q17) -> 18.75 | T17: =U17/S17 -> 12.053333 | U17: =SUM(E17-R17) -> 226
A18: 2010 | C18: Malbec | D18: 12 | E18: 168 | F18: 16 | G18: 8 | H18: 7 | I18: 12 | R18: =SUM(F18:Q18) -> 43 | S18: =AVERAGE(F18:Q18) -> 10.75 | T18: =U18/S18 -> 11.627907 | U18: =SUM(E18-R18) -> 125 | V18: 3
A19: 2010 | C19: Ameritage Res | D19: 22 | E19: 573 | F19: 8 | G19: 24 | H19: 27 | I19: 20 | R19: =SUM(F19:Q19) -> 79 | S19: =AVERAGE(F19:Q19) -> 19.75 | T19: =U19/S19 -> 25.012658 | U19: =SUM(E19-R19) -> 494 | V19: 5
A20: 2010 | C20: Ameritage | D20: 37 | E20: 396 | F20: 43 | G20: 21 | H20: 9 | I20: 24 | R20: =SUM(F20:Q20) -> 97 | S20: =AVERAGE(F20:Q20) -> 24.25 | T20: =U20/S20 -> 12.329897 | U20: =SUM(E20-R20) -> 299
A21: 2010 | C21: LH Petit Manseng | D21: 13 | E21: 210 | F21: 20 | G21: 6 | H21: 6 | I21: 14 | R21: =SUM(F21:Q21) -> 46 | S21: =AVERAGE(F21:Q21) -> 11.5 | T21: =U21/S21 -> 14.26087 | U21: =SUM(E21-R21) -> 164
F22: 1
A23: 2011 | C23: Petit Manseng | D23: 25 | E23: 281 | F23: 46 | G23: 25 | H23: 210 | R23: =SUM(F23:Q23) -> 281 | S23: =AVERAGE(F23:Q23) -> 93.666667 | T23: =U23/S23 -> 0 | U23: =SUM(E23-R23) -> 0 | V23: 19 remaining cases, 25 sold, the remainder recycled.
A24: 2011 | C24: Chardonnay | D24: 38 | E24: 535 | F24: 1 | G24: 0 | H24: 0 | I24: 4 | R24: =SUM(F24:Q24) -> 5 | S24: =AVERAGE(F24:Q24) -> 1.25 | T24: =U24/S24 -> 424 | U24: =SUM(E24-R24) -> 530
A25: 2011 | C25: Viognier | D25: 31 | E25: 487 | F25: 1 | G25: 5 | H25: 3 | I25: 12 | R25: =SUM(F25:Q25) -> 21 | S25: =AVERAGE(F25:Q25) -> 5.25 | T25: =U25/S25 -> 88.761905 | U25: =SUM(E25-R25) -> 466
A26: 2011 | C26: Riesling | D26: 29 | E26: 147 | F26: 19 | G26: 0 | H26: 128 | R26: =SUM(F26:Q26) -> 147 | S26: =AVERAGE(F26:Q26) -> 49 | T26: =U26/S26 -> 0 | U26: =SUM(E26-R26) -> 0 | V26: All 128 cases recycled into other bulk wines.
A27: 2011 | C27: Merlot | D27: 16 | E27: 243 | F27: 2 | G27: 0 | H27: 0 | I27: 0 | R27: =SUM(F27:Q27) -> 2 | S27: =AVERAGE(F27:Q27) -> 0.5 | T27: =U27/S27 -> 482 | U27: =SUM(E27-R27) -> 241
A28: 2011 | C28: Cab Franc | D28: 29 | E28: 179 | F28: 1 | G28: 0 | H28: 0 | I28: 0 | R28: =SUM(F28:Q28) -> 1 | S28: =AVERAGE(F28:Q28) -> 0.25 | T28: =U28/S28 -> 712 | U28: =SUM(E28-R28) -> 178
A29: 2011 | C29: Cab Sauv | D29: 25 | E29: 202 | F29: 5 | G29: 0 | H29: 3 | I29: 1 | R29: =SUM(F29:Q29) -> 9 | S29: =AVERAGE(F29:Q29) -> 2.25 | T29: =U29/S29 -> 85.777778 | U29: =SUM(E29-R29) -> 193
A30: 2011 | C30: Petit Verdot | D30: 21 | E30: 171 | F30: 2 | G30: 6 | H30: 0 | I30: 0 | R30: =SUM(F30:Q30) -> 8 | S30: =AVERAGE(F30:Q30) -> 2 | T30: =U30/S30 -> 81.5 | U30: =SUM(E30-R30) -> 163
A31: 2011 | C31: Ameritage | D31: 37 | E31: 344 | F31: 1 | G31: 0 | H31: 11 | I31: 0 | R31: =SUM(F31:Q31) -> 12 | S31: =AVERAGE(F31:Q31) -> 3 | T31: =U31/S31 -> 110.66667 | U31: =SUM(E31-R31) -> 332
A32: 2011 | C32: LH Tram | D32: 13 | E32: 359 | F32: 1 | G32: 4 | H32: 0 | I32: 0 | R32: =SUM(F32:Q32) -> 5 | S32: =AVERAGE(F32:Q32) -> 1.25 | T32: =U32/S32 -> 283.2 | U32: =SUM(E32-R32) -> 354
A34: 2012 | C34: Riesling | E34: 547 | G34: 1 | H34: 89 | I34: 54 | R34: =SUM(F34:Q34) -> 144 | S34: =AVERAGE(F34:Q34) -> 48 | T34: =U34/S34 -> 8.3958333 | U34: =SUM(E34-R34) -> 403
A35: 2012 | C35: Petite Manseng | E35: 332 | I35: 37 | R35: =SUM(F35:Q35) -> 37 | S35: =AVERAGE(F35:Q35) -> 37 | T35: =U35/S35 -> 7.972973 | U35: =SUM(E35-R35) -> 295
R36: =SUM(F36:Q36) -> 0 | S36: =AVERAGE(F36:Q36) -> #DIV/0! | T36: =U36/S36 -> #DIV/0! | U36: =SUM(E36-R36) -> 0
R37: =SUM(F37:Q37) -> 0 | S37: =AVERAGE(F37:Q37) -> #DIV/0! | T37: =U37/S37 -> #DIV/0! | U37: =SUM(E37-R37) -> 0
R38: =SUM(F38:Q38) -> 0 | S38: =AVERAGE(F38:Q38) -> #DIV/0! | T38: =U38/S38 -> #DIV/0! | U38: =SUM(E38-R38) -> 0
R39: =SUM(F39:Q39) -> 0 | S39: =AVERAGE(F39:Q39) -> #DIV/0! | T39: =U39/S39 -> #DIV/0! | U39: =SUM(E39-R39) -> 0
R40: =SUM(F40:Q40) -> 0 | S40: =AVERAGE(F40:Q40) -> #DIV/0! | T40: =U40/S40 -> #DIV/0! | U40: =SUM(E40-R40) -> 0
R41: =SUM(F41:Q41) -> 0 | S41: =AVERAGE(F41:Q41) -> #DIV/0! | T41: =U41/S41 -> #DIV/0! | U41: =SUM(E41-R41) -> 0
A43: 2009 | E43: =SUM(E7:E9) -> 152 | F43: =SUM(F7:F9) -> 57 | G43: =SUM(G7:G9) -> 17 | H43: =SUM(H7:H9) -> 14 | I43: =SUM(I7:I9) -> 34 | J43: =SUM(J7:J9) -> 0 | K43: =SUM(K7:K9) -> 0 | L43: =SUM(L7:L9) -> 0 | ... R43: =SUM(R7:R9) -> 122 | S43: =AVERAGE(F43:Q43) -> 10.166667 | T43: =U43/S43 -> 2.9508197 | U43: =SUM(U7:U9) -> 30
A44: 2010 | E44: =SUM(E11:E21) -> 2967 | F44: =SUM(F11:F21) -> 196 | G44: =SUM(G11:G21) -> 171 | H44: =SUM(H11:H21) -> 149 | I44: =SUM(I11:I21) -> 230 | J44: =SUM(J11:J21) -> 0 | K44: =SUM(K11:K21) -> 0 | L44: =SUM(L11:L21) -> 0 | ... R44: =SUM(R11:R21) -> 746 | S44: =AVERAGE(F44:Q44) -> 62.166667 | T44: =U44/S44 -> 35.726542 | U44: =SUM(U11:U21) -> 2221
A45: 2011 | E45: =SUM(E23:E41) -> 3827 | F45: =SUM(F23:F41) -> 79 | G45: =SUM(G23:G41) -> 41 | H45: =SUM(H23:H41) -> 444 | I45: =SUM(I23:I41) -> 108 | J45: =SUM(J23:J41) -> 0 | K45: =SUM(K23:K41) -> 0 | L45: =SUM(L23:L41) -> 0 | ... R45: =SUM(R23:R41) -> 672 | S45: =AVERAGE(F45:Q45) -> 56 | T45: =U45/S45 -> 56.339286 | U45: =SUM(U23:U41) -> 3155
A46: 2012
A47: TOTAL | E47: =SUM(E43:E46) -> 6946 | F47: =SUM(F43:F46) -> 332 | G47: =SUM(G43:G46) -> 229 | H47: =SUM(H43:H46) -> 607 | I47: =SUM(I43:I46) -> 372 | J47: =SUM(J43:J46) -> 0 | K47: =SUM(K43:K46) -> 0 | L47: =SUM(L43:L46) -> 0 | ... S47: =SUM(S43:S46) -> 128.33333 | T47: =U47/S47 -> 42.124675 | U47: =SUM(U43:U46) -> 5406
...

Sheet 2014
B7: CASES MOVED PER MONTH
A8: ABC # | B8: Year | C8: Wine | D8: 2013 Monthly Avg. | E8: 2014 BOY Inventory | F8: Jan | G8: Feb | H8: Mar | I8: Apr | J8: May | K8: Jun | L8: Jul | M8: Aug | N8: Sep | O8: Oct | P8: Nov | Q8: Dec | R8: Totals | S8: 2014 Monthly Avg. | T8: Months Left | U8: Remaining Inventory
A10: 22382 | B10: 2010 | C10: Cab Franc | D10: 29 | E10: 36 | F10: 20 | G10: 16 | R10: =SUM(F10:Q10) -> 36 | S10: =AVERAGE(F10:Q10) -> 18 | T10: =U10/S10 -> 0 | U10: =SUM(E10-R10) -> 0
A11: 22834 | B11: 2010 | C11: Merlot | D11: 16 | E11: 137 | F11: 20 | G11: 20 | H11: 6 | I11: 9 | J11: 24 | K11: 17 | L11: 22 | M11: 10 | R11: =SUM(F11:Q11) -> 128 | S11: =AVERAGE(F11:Q11) -> 16 | T11: =U11/S11 -> 0 | U11: 0
A12: 18004 | B12: 2010 | C12: Malbec | D12: 12 | E12: 32 | F12: 11 | G12: 21 | R12: =SUM(F12:Q12) -> 32 | S12: =AVERAGE(F12:Q12) -> 16 | T12: =U12/S12 -> 0 | U12: =SUM(E12-R12) -> 0
A13: 34641 | B13: 2010 | C13: Ameritage Res | D13: 22 | E13: 278 | F13: 9 | G13: 17 | H13: 22 | I13: 24 | J13: 23 | K13: 47 | L13: 29 | M13: 31 | N13: 28 | O13: 48 | R13: =SUM(F13:Q13) -> 278 | S13: =AVERAGE(F13:Q13) -> 27.8 | T13: =U13/S13 -> 0 | U13: =SUM(E13-R13) -> 0
A14: 22921 | B14: 2010 | C14: Ameritage | D14: 37 | E14: 150 | F14: 38 | G14: 59 | H14: 21 | I14: 12 | J14: 5 | K14: 15 | R14: =SUM(F14:Q14) -> 150 | S14: =AVERAGE(F14:Q14) -> 25 | T14: =U14/S14 -> 0 | U14: =SUM(E14-R14) -> 0
A15: 38269 | B15: 2010 | C15: LH Petit Manseng | D15: 13 | E15: 69 | F15: 5 | G15: 0 | H15: 14 | I15: 9 | J15: 10 | K15: 16 | R15: =SUM(F15:Q15) -> 54 | S15: =AVERAGE(F15:Q15) -> 9 | T15: =U15/S15 -> 0 | U15: 0
F16: 1
A17: 57630 | B17: 2011 | C17: Chardonnay | D17: 38 | E17: 458 | F17: 1 | G17: 17 | H17: 21 | I17: 33 | J17: 34 | K17: 28 | L17: 29 | M17: 24 | N17: 60 | O17: 34 | P17: 76 | Q17: 21 | R17: =SUM(F17:Q17) -> 378 | S17: =AVERAGE(F17:Q17) -> 31.5 | T17: =U17/S17 -> 2.5396825 | U17: =SUM(E17-R17) -> 80
A18: 57632 | B18: 2011 | C18: Viognier | D18: 31 | E18: 95 | F18: 1 | G18: 19 | H18: 18 | I18: 24 | J18: 33 | R18: =SUM(F18:Q18) -> 95 | S18: =AVERAGE(F18:Q18) -> 19 | T18: =U18/S18 -> 0 | U18: =SUM(E18-R18) -> 0
A19: 22384 | B19: 2011 | C19: Merlot | D19: 16 | E19: 241 | F19: 9 | G19: 1 | H19: 0 | I19: 0 | J19: 0 | K19: 7 | L19: 0 | M19: 0 | N19: 107 | O19: 36 | P19: 19 | Q19: 16 | R19: =SUM(F19:Q19) -> 195 | S19: =AVERAGE(F19:Q19) -> 16.25 | T19: =U19/S19 -> 2.8307692 | U19: =SUM(E19-R19) -> 46
A20: 22382 | B20: 2011 | C20: Cab Franc | D20: 29 | E20: 179 | F20: 6 | G20: 19 | H20: 20 | I20: 25 | J20: 32 | K20: 16 | L20: 43 | M20: 18 | R20: =SUM(F20:Q20) -> 179 | S20: =AVERAGE(F20:Q20) -> 22.375 | T20: =U20/S20 -> 0 | U20: =SUM(E20-R20) -> 0
A21: 28361 | B21: 2011 | C21: Cab Sauv | D21: 25 | E21: 174 | F21: 11 | G21: 9 | H21: 18 | I21: 15 | J21: 25 | K21: 17 | L21: 24 | M21: 11 | N21: 21 | O21: 13 | P21: 10 | R21: =SUM(F21:Q21) -> 174 | S21: =AVERAGE(F21:Q21) -> 15.818182 | T21: =U21/S21 -> 0 | U21: =SUM(E21-R21) -> 0
A22: 27736 | B22: 2011 | C22: Petit Verdot | D22: 21 | E22: 153 | F22: 7 | G22: 13 | H22: 15 | I22: 17 | J22: 18 | K22: 15 | L22: 4 | M22: 8 | N22: 39 | O22: 17 | R22: =SUM(F22:Q22) -> 153 | S22: =AVERAGE(F22:Q22) -> 15.3 | T22: =U22/S22 -> 0 | U22: =SUM(E22-R22) -> 0
A23: 22921 | B23: 2011 | C23: Ameritage | D23: 37 | E23: 328 | F23: 1 | G23: 0 | H23: 9 | I23: 0 | J23: 25 | K23: 65 | L23: 37 | M23: 20 | N23: 38 | O23: 44 | P23: 26 | Q23: 29 | R23: =SUM(F23:Q23) -> 294 | S23: =AVERAGE(F23:Q23) -> 24.5 | T23: =U23/S23 -> 1.3877551 | U23: =SUM(E23-R23) -> 34
A24: 26415 | B24: 2011 | C24: LH Tram | D24: 13 | E24: 263 | F24: 8 | G24: 9 | H24: 9 | I24: 33 | J24: 5 | K24: 0 | L24: 17 | M24: 9 | N24: 53 | O24: 0 | P24: 0 | Q24: 4 | R24: =SUM(F24:Q24) -> 147 | S24: =AVERAGE(F24:Q24) -> 12.25 | T24: =U24/S24 -> 9.4693878 | U24: =SUM(E24-R24) -> 116
A26: 11198 | B26: 2012 | C26: Petite Manseng | E26: 70 | F26: 14 | G26: 20 | H26: 19 | I26: 17 | R26: =SUM(F26:Q26) -> 70 | S26: =AVERAGE(F26:Q26) -> 17.5 | T26: =U26/S26 -> 0 | U26: =SUM(E26-R26) -> 0
A27: 57632 | B27: 2012 | C27: Viognier | E27: 275 | F27: 20 | G27: 0 | H27: 2 | I27: 0 | J27: 16 | K27: 43 | L27: 39 | M27: 38 | N27: 87 | O27: 30 | R27: =SUM(F27:Q27) -> 275 | S27: =AVERAGE(F27:Q27) -> 27.5 | T27: =U27/S27 -> 0 | U27: =SUM(E27-R27) -> 0
A28: 57630 | B28: 2012 | C28: Chardonnay | E28: 334 | F28: 28 | G28: 2 | H28: 0 | I28: 8 | J28: 0 | K28: 8 | L28: 10 | M28: 3 | N28: 22 | O28: 10 | P28: 0 | Q28: 23 | R28: =SUM(F28:Q28) -> 114 | S28: =AVERAGE(F28:Q28) -> 9.5 | T28: =U28/S28 -> 23.157895 | U28: =SUM(E28-R28) -> 220
A29: 22384 | B29: 2012 | C29: Merlot | E29: 395 | F29: 22 | G29: 0 | H29: 0 | I29: 0 | J29: 0 | K29: 0 | L29: 0 | M29: 0 | N29: 26 | O29: 0 | P29: 30 | Q29: 2 | R29: =SUM(F29:Q29) -> 80 | S29: =AVERAGE(F29:Q29) -> 6.6666667 | T29: =U29/S29 -> 47.25 | U29: =SUM(E29-R29) -> 315
A30: 22382 | B30: 2012 | C30: Cab Franc | E30: 409 | F30: 23 | G30: 1 | H30: 2 | I30: 0 | J30: 0 | K30: 4 | L30: 0 | M30: 4 | N30: 0 | O30: 39 | P30: 32 | Q30: 19 | R30: =SUM(F30:Q30) -> 124 | S30: =AVERAGE(F30:Q30) -> 10.333333 | T30: =U30/S30 -> 27.580645 | U30: =SUM(E30-R30) -> 285
A31: 27736 | B31: 2012 | C31: Petit Verdot | E31: 292 | F31: 1 | G31: 6 | H31: 0 | I31: 0 | J31: 0 | K31: 0 | L31: 5 | M31: 4 | N31: 8 | O31: 8 | P31: 19 | Q31: 18 | R31: =SUM(F31:Q31) -> 69 | S31: =AVERAGE(F31:Q31) -> 5.75 | T31: =U31/S31 -> 38.782609 | U31: =SUM(E31-R31) -> 223
A32: 28361 | B32: 2012 | C32: Cab Sauv | E32: 497 | F32: 28 | G32: 1 | H32: 0 | I32: 0 | J32: 0 | K32: 10 | L32: 7 | M32: 0 | N32: 0 | O32: 17 | P32: 9 | Q32: 19 | R32: =SUM(F32:Q32) -> 91 | S32: =AVERAGE(F32:Q32) -> 7.5833333 | T32: =U32/S32 -> 53.538462 | U32: =SUM(E32-R32) -> 406
A33: 22921 | B33: 2012 | C33: Ameritage | E33: 579 | F33: 1 | G33: 4 | H33: 0 | I33: 0 | J33: 0 | K33: 23 | L33: 15 | M33: 6 | N33: 22 | O33: 55 | P33: 8 | Q33: 20 | R33: =SUM(F33:Q33) -> 154 | S33: =AVERAGE(F33:Q33) -> 12.833333 | T33: =U33/S33 -> 33.116883 | U33: =SUM(E33-R33) -> 425
A34: 34641 | B34: 2012 | C34: Ameritage Reserve | E34: 294 | F34: 4 | G34: 0 | H34: 10 | I34: 0 | J34: 0 | K34: 7 | L34: 17 | M34: 0 | N34: 6 | O34: 0 | P34: 11 | Q34: 33 | R34: =SUM(F34:Q34) -> 88 | S34: =AVERAGE(F34:Q34) -> 7.3333333 | T34: =U34/S34 -> 28.090909 | U34: =SUM(E34-R34) -> 206
A35: 30306 | B35: 2012 | C35: Vin de Sol | E35: 41 | F35: 11 | G35: 9 | H35: 9 | I35: 5 | J35: 7 | R35: =SUM(F35:Q35) -> 41 | S35: =AVERAGE(F35:Q35) -> 8.2 | T35: =U35/S35 -> 0 | U35: =SUM(E35-R35) -> 0
C36: 1991 Brut | E36: 15 | F36: 11 | G36: 1 | H36: 1 | I36: 0 | J36: 0 | R36: =SUM(F36:Q36) -> 13 | S36: =AVERAGE(F36:Q36) -> 2.6 | T36: =U36/S36 -> 0 | U36: 0
A38: 11198 | B38: 2013 | C38: Petit Manseng | E38: 342 | H38: 1 | I38: 25 | J38: 56 | K38: 35 | L38: 48 | M38: 19 | N38: 40 | O38: 31 | P38: 23 | Q38: 16 | R38: =SUM(F38:Q38) -> 294 | S38: =AVERAGE(F38:Q38) -> 29.4 | T38: =U38/S38 -> 1.6326531 | U38: =SUM(E38-R38) -> 48
A39: 57631 | B39: 2013 | C39: Riesling | E39: 358 | H39: 1 | I39: 60 | J39: 68 | K39: 35 | L39: 48 | M39: 24 | N39: 38 | O39: 35 | P39: 23 | Q39: 17 | R39: =SUM(F39:Q39) -> 349 | S39: =AVERAGE(F39:Q39) -> 34.9 | T39: =U39/S39 -> 0.25787966 | U39: =SUM(E39-R39) -> 9
A40: 57632 | B40: 2013 | C40: Viognier | E40: 589 | J40: 1 | L40: 22 | M40: 9 | N40: 9 | O40: 30 | P40: 76 | Q40: 19 | R40: =SUM(F40:Q40) -> 166 | S40: =AVERAGE(F40:Q40) -> 23.714286 | T40: =U40/S40 -> 17.837349 | U40: =SUM(E40-R40) -> 423
A41: 57630 | B41: 2013 | C41: Chardonnay | E41: 608 | K41: 1 | L41: 5 | M41: 0 | N41: 22 | O41: 2 | P41: 12 | Q41: 10 | R41: =SUM(F41:Q41) -> 52 | S41: =AVERAGE(F41:Q41) -> 7.4285714 | T41: =U41/S41 -> 74.846154 | U41: =SUM(E41-R41) -> 556
A42: 22382 | B42: 2013 | C42: Cab Franc | E42: 343 | L42: 1 | M42: 0 | N42: 9 | O42: 9 | P42: 12 | Q42: 9 | R42: =SUM(F42:Q42) -> 40 | S42: =AVERAGE(F42:Q42) -> 6.6666667 | T42: =U42/S42 -> 45.45 | U42: =SUM(E42-R42) -> 303
B43: 2013 | C43: Cab Franc Res | E43: 280 | M43: 1 | N43: 24 | O43: 13 | P43: 11 | Q43: 29 | R43: =SUM(F43:Q43) -> 78 | S43: =AVERAGE(F43:Q43) -> 15.6 | T43: =U43/S43 -> 12.948718 | U43: =SUM(E43-R43) -> 202
A44: 22384 | B44: 2013 | C44: Merlot | E44: 290 | L44: 1 | M44: 0 | N44: 9 | O44: 11 | P44: 13 | Q44: 0 | R44: =SUM(F44:Q44) -> 34 | S44: =AVERAGE(F44:Q44) -> 5.6666667 | T44: =U44/S44 -> 45.176471 | U44: =SUM(E44-R44) -> 256
A45: 27736 | B45: 2013 | C45: Petit Verdot | E45: 395 | M45: 1 | N45: 19 | O45: 9 | P45: 2 | Q45: 13 | R45: =SUM(F45:Q45) -> 44 | S45: =AVERAGE(F45:Q45) -> 8.8 | T45: =U45/S45 -> 39.886364 | U45: =SUM(E45-R45) -> 351
A46: 28361 | B46: 2013 | C46: Cab Sauv | E46: 282 | Q46: 1 | R46: =SUM(F46:Q46) -> 1 | S46: =AVERAGE(F46:Q46) -> 1 | T46: =U46/S46 -> 281 | U46: =SUM(E46-R46) -> 281
A47: 22921 | B47: 2013 | C47: Ameritage | E47: 717 | Q47: 1 | R47: =SUM(F47:Q47) -> 1 | S47: =AVERAGE(F47:Q47) -> 1 | T47: =U47/S47 -> 716 | U47: =SUM(E47-R47) -> 716
A48: 34641 | B48: 2013 | C48: Ameritage Res | E48: 427 | Q48: 1 | R48: =SUM(F48:Q48) -> 1 | S48: =AVERAGE(F48:Q48) -> 1 | T48: =U48/S48 -> 426 | U48: =SUM(E48-R48) -> 426
B49: 2013 | C49: Black Ops | E49: 134 | Q49: 1 | R49: =SUM(F49:Q49) -> 1 | S49: =AVERAGE(F49:Q49) -> 1 | T49: =U49/S49 -> 133 | U49: =SUM(E49-R49) -> 133
...

Sheet 2015
B7: CASES MOVED PER MONTH
A8: ABC # | B8: Year | C8: Wine | D8: 2014 Monthly Avg. | E8: 2015 BOY Inventory | F8: Jan | G8: Feb | H8: Mar | I8: Apr | J8: May | K8: Jun | L8: Jul | M8: Aug | N8: Sep | O8: Oct | P8: Nov | Q8: Dec | R8: Totals | S8: 2015 Monthly Avg. | T8: Months Left | U8: Remaining Inventory
F9: 1
A10: 57630 | B10: 2011 | C10: Chardonnay | D10: 32 | E10: 80 | F10: 34 | G10: 12 | H10: 15 | I10: 10 | J10: 9 | R10: =SUM(F10:Q10) -> 80 | S10: =AVERAGE(F10:Q10) -> 16 | T10: =U10/S10 -> 0 | U10: =SUM(E10-R10) -> 0
A11: 22384 | B11: 2011 | C11: Merlot | D11: 16 | E11: 46 | F11: 18 | G11: 11 | H11: 12 | I11: 5 | R11: =SUM(F11:Q11) -> 46 | S11: =AVERAGE(F11:Q11) -> 11.5 | T11: =U11/S11 -> 0 | U11: =SUM(E11-R11) -> 0
A12: 22921 | B12: 2011 | C12: Ameritage | D12: 25 | E12: 34 | F12: 25 | G12: 9 | R12: =SUM(F12:Q12) -> 34 | S12: =AVERAGE(F12:Q12) -> 17 | T12: =U12/S12 -> 0 | U12: =SUM(E12-R12) -> 0
A13: 26415 | B13: 2011 | C13: LH Tram | D13: 12 | E13: 116 | F13: 13 | G13: 4 | H13: 19 | I13: 16 | J13: 15 | K13: 11 | L13: 22 | M13: 16 | R13: =SUM(F13:Q13) -> 116 | S13: =AVERAGE(F13:Q13) -> 14.5 | T13: =U13/S13 -> 0 | U13: =SUM(E13-R13) -> 0
A15: 57630 | B15: 2012 | C15: Chardonnay | D15: 45 | E15: 220 | F15: 6 | G15: 13 | H15: 5 | I15: 9 | J15: 13 | K15: 14 | L15: 48 | M15: 34 | N15: 36 | O15: 17 | P15: 2 | R15: =SUM(F15:Q15) -> 197 | S15: =AVERAGE(F15:Q15) -> 17.909091 | T15: =U15/S15 -> 1.284264 | U15: =SUM(E15-R15) -> 23
A16: 22384 | B16: 2012 | C16: Merlot | D16: 36 | E16: 315 | F16: 3 | G16: 1 | H16: 2 | I16: 0 | J16: 0 | K16: 0 | L16: 6 | M16: 13 | N16: 18 | O16: 26 | P16: 24 | Q16: 17 | R16: =SUM(F16:Q16) -> 110 | S16: =AVERAGE(F16:Q16) -> 9.1666667 | T16: =U16/S16 -> 22.363636 | U16: =SUM(E16-R16) -> 205
A17: 22382 | B17: 2012 | C17: Cab Franc | D17: 29 | E17: 285 | F17: 13 | G17: 24 | H17: 15 | I17: 35 | J17: 20 | K17: 26 | L17: 22 | M17: 24 | N17: 31 | O17: 41 | P17: 28 | Q17: 6 | R17: =SUM(F17:Q17) -> 285 | S17: =AVERAGE(F17:Q17) -> 23.75 | T17: =U17/S17 -> 0 | U17: =SUM(E17-R17) -> 0
A18: 27736 | B18: 2012 | C18: Petit Verdot | D18: 22 | E18: 223 | F18: 29 | G18: 11 | H18: 12 | I18: 25 | J18: 17 | K18: 13 | L18: 20 | M18: 16 | N18: 20 | O18: 26 | P18: 19 | Q18: 15 | R18: =SUM(F18:Q18) -> 223 | S18: =AVERAGE(F18:Q18) -> 18.583333 | T18: =U18/S18 -> 0 | U18: =SUM(E18-R18) -> 0
A19: 28361 | B19: 2012 | C19: Cab Sauv | D19: 22 | E19: 406 | F19: 27 | G19: 13 | H19: 15 | I19: 26 | J19: 27 | K19: 23 | L19: 32 | M19: 22 | N19: 17 | O19: 56 | P19: 32 | Q19: 21 | R19: =SUM(F19:Q19) -> 311 | S19: =AVERAGE(F19:Q19) -> 25.916667 | T19: =U19/S19 -> 3.6655949 | U19: =SUM(E19-R19) -> 95
A20: 22921 | B20: 2012 | C20: Ameritage | D20: 50 | E20: 425 | F20: 43 | G20: 35 | H20: 40 | I20: 55 | J20: 41 | K20: 48 | L20: 40 | M20: 47 | N20: 64 | O20: 6 | R20: =SUM(F20:Q20) -> 419 | S20: =AVERAGE(F20:Q20) -> 41.9 | T20: =U20/S20 -> 0.14319809 | U20: =SUM(E20-R20) -> 6
A21: 34641 | B21: 2012 | C21: Ameritage Reserve | D21: 31 | E21: 206 | F21: 26 | G21: 22 | H21: 29 | I21: 35 | J21: 33 | K21: 25 | L21: 32 | M21: 4 | R21: =SUM(F21:Q21) -> 206 | S21: =AVERAGE(F21:Q21) -> 25.75 | T21: =U21/S21 -> 0 | U21: =SUM(E21-R21) -> 0
A23: 11198 | B23: 2013 | C23: Petit Manseng | D23: 30 | E23: 48 | F23: 24 | G23: 24 | R23: =SUM(F23:Q23) -> 48 | S23: =AVERAGE(F23:Q23) -> 24 | T23: =U23/S23 -> 0 | U23: =SUM(E23-R23) -> 0
A24: 57631 | B24: 2013 | C24: Riesling | D24: 35 | E24: 9 | F24: 9 | R24: =SUM(F24:Q24) -> 9 | S24: =AVERAGE(F24:Q24) -> 9 | T24: =U24/S24 -> 0 | U24: =SUM(E24-R24) -> 0
A25: 57632 | B25: 2013 | C25: Viognier | D25: 45 | E25: 423 | F25: 36 | G25: 22 | H25: 0 | I25: 10 | J25: 55 | K25: 39 | L25: 49 | M25: 34 | N25: 42 | O25: 49 | P25: 36 | Q25: 29 | R25: =SUM(F25:Q25) -> 401 | S25: =AVERAGE(F25:Q25) -> 33.416667 | T25: =U25/S25 -> 0.65835411 | U25: =SUM(E25-R25) -> 22
A26: 57630 | B26: 2013 | C26: Chardonnay | D26: 45 | E26: 556 | F26: 1 | G26: 10 | H26: 5 | I26: 11 | J26: 5 | K26: 7 | L26: 3 | M26: 4 | N26: 3 | O26: 29 | P26: 39 | Q26: 37 | R26: =SUM(F26:Q26) -> 154 | S26: =AVERAGE(F26:Q26) -> 12.833333 | T26: =U26/S26 -> 31.324675 | U26: =SUM(E26-R26) -> 402
A27: 22382 | B27: 2013 | C27: Cab Franc | D27: 29 | E27: 303 | F27: 1 | G27: 1 | H27: 21 | I27: 0 | J27: 1 | K27: 4 | L27: 20 | M27: 2 | N27: 5 | O27: 16 | P27: 12 | Q27: 33 | R27: =SUM(F27:Q27) -> 116 | S27: =AVERAGE(F27:Q27) -> 9.6666667 | T27: =U27/S27 -> 19.344828 | U27: =SUM(E27-R27) -> 187
A28: 84802 | B28: 2013 | C28: Cab Franc Res | D28: 18 | E28: 202 | F28: 21 | G28: 8 | H28: 11 | I28: 6 | J28: 8 | K28: 6 | L28: 8 | M28: 5 | N28: 8 | O28: 15 | P28: 9 | Q28: 20 | R28: =SUM(F28:Q28) -> 125 | S28: =AVERAGE(F28:Q28) -> 10.416667 | T28: =U28/S28 -> 7.392 | U28: =SUM(E28-R28) -> 77
A29: 22384 | B29: 2013 | C29: Merlot | D29: 36 | E29: 256 | F29: 1 | G29: 0 | H29: 0 | I29: 0 | J29: 0 | K29: 0 | L29: 2 | M29: 2 | N29: 1 | P29: 1 | Q29: 4 | R29: =SUM(F29:Q29) -> 11 | S29: =AVERAGE(F29:Q29) -> 1 | T29: =U29/S29 -> 245 | U29: =SUM(E29-R29) -> 245
A30: 27736 | B30: 2013 | C30: Petit Verdot | D30: 22 | E30: 351 | F30: 8 | G30: 2 | H30: 6 | I30: 7 | J30: 1 | K30: 7 | L30: 14 | M30: 6 | N30: 9 | O30: 23 | P30: 18 | Q30: 20 | R30: =SUM(F30:Q30) -> 121 | S30: =AVERAGE(F30:Q30) -> 10.083333 | T30: =U30/S30 -> 22.809917 | U30: =SUM(E30-R30) -> 230
A31: 28361 | B31: 2013 | C31: Cab Sauv | D31: 22 | E31: 281 | F31: 1 | G31: 0 | H31: 2 | I31: 0 | J31: 2 | K31: 0 | L31: 4 | M31: 3 | N31: 1 | P31: 0 | Q31: 11 | R31: =SUM(F31:Q31) -> 24 | S31: =AVERAGE(F31:Q31) -> 2.1818182 | T31: =U31/S31 -> 117.79167 | U31: =SUM(E31-R31) -> 257
A32: 22921 | B32: 2013 | C32: Ameritage | D32: 50 | E32: 716 | F32: 20 | G32: 4 | H32: 1 | I32: 4 | J32: 2 | K32: 3 | L32: 16 | M32: 5 | N32: 1 | O32: 67 | P32: 59 | Q32: 57 | R32: =SUM(F32:Q32) -> 239 | S32: =AVERAGE(F32:Q32) -> 19.916667 | T32: =U32/S32 -> 23.949791 | U32: =SUM(E32-R32) -> 477
A33: 34641 | B33: 2013 | C33: Ameritage Res | D33: 31 | E33: 426 | F33: 1 | G33: 2 | H33: 2 | I33: 2 | J33: 2 | K33: 3 | L33: 8 | M33: 25 | N33: 25 | O33: 37 | P33: 25 | Q33: 23 | R33: =SUM(F33:Q33) -> 155 | S33: =AVERAGE(F33:Q33) -> 12.916667 | T33: =U33/S33 -> 20.980645 | U33: =SUM(E33-R33) -> 271
A34: 86051 | B34: 2013 | C34: Black Ops | E34: 133 | F34: 6 | G34: 10 | H34: 9 | I34: 13 | J34: 13 | K34: 18 | L34: 19 | M34: 16 | N34: 16 | O34: 7 | P34: 6 | R34: =SUM(F34:Q34) -> 133 | S34: =AVERAGE(F34:Q34) -> 12.090909 | T34: =U34/S34 -> 0 | U34: =SUM(E34-R34) -> 0
A35: 84251 | B35: 2013 | C35: Syrah | E35: 68 | F35: 11 | G35: 5 | H35: 2 | I35: 4 | J35: 2 | K35: 7 | L35: 7 | M35: 5 | N35: 4 | O35: 11 | P35: 6 | R35: =SUM(F35:Q35) -> 64 | S35: =AVERAGE(F35:Q35) -> 5.8181818 | T35: =U35/S35 -> 0.6875 | U35: =SUM(E35-R35) -> 4
A37: 11198 | B37: 2014 | C37: Petit Manseng | E37: 336 | I37: 27 | J37: 41 | K37: 31 | L37: 38 | M37: 28 | N37: 31 | O37: 54 | P37: 27 | R37: =SUM(F37:Q37) -> 277 | S37: =AVERAGE(F37:Q37) -> 34.625 | T37: =U37/S37 -> 1.7039711 | U37: =SUM(E37-R37) -> 59
A38: 57631 | B38: 2014 | C38: Dry Rielsing | E38: 113 | I38: 36 | J38: 12 | K38: 13 | L38: 23 | M38: 6 | N38: 10 | O38: 11 | P38: 2 | R38: =SUM(F38:Q38) -> 113 | S38: =AVERAGE(F38:Q38) -> 14.125 | T38: =U38/S38 -> 0 | U38: =SUM(E38-R38) -> 0
A39: 57631 | B39: 2014 | C39: Riesling | E39: 268 | I39: 44 | J39: 46 | K39: 41 | L39: 47 | M39: 42 | N39: 43 | O39: 5 | R39: =SUM(F39:Q39) -> 268 | S39: =AVERAGE(F39:Q39) -> 38.285714 | T39: =U39/S39 -> 0 | U39: =SUM(E39-R39) -> 0
A40: 57632 | B40: 2014 | C40: Viognier | E40: 504 | K40: 0 | L40: 21 | M40: 7 | N40: 8 | O40: 8 | P40: 7 | Q40: 12 | R40: =SUM(F40:Q40) -> 63 | S40: =AVERAGE(F40:Q40) -> 9 | T40: =U40/S40 -> 49 | U40: =SUM(E40-R40) -> 441
A41: 57630 | B41: 2014 | C41: Chardonnay | E41: 536 | L41: 10 | M41: 5 | N41: 0 | O41: 26 | P41: 13 | Q41: 14 | R41: =SUM(F41:Q41) -> 68 | S41: =AVERAGE(F41:Q41) -> 11.333333 | T41: =U41/S41 -> 41.294118 | U41: =SUM(E41-R41) -> 468
A42: 22382 | B42: 2014 | C42: Cab Franc | E42: 356 | L42: 12 | M42: 8 | N42: 10 | O42: 8 | P42: 1 | Q42: 11 | R42: =SUM(F42:Q42) -> 50 | S42: =AVERAGE(F42:Q42) -> 8.3333333 | T42: =U42/S42 -> 36.72 | U42: =SUM(E42-R42) -> 306
A43: 84802 | B43: 2014 | C43: Cab Franc Res | E43: 273 | Q43: 2 | R43: =SUM(F43:Q43) -> 2 | S43: =AVERAGE(F43:Q43) -> 2 | T43: =U43/S43 -> 135.5 | U43: =SUM(E43-R43) -> 271
A44: 22384 | B44: 2014 | C44: Merlot | E44: 247 | L44: 0 | M44: 0 | N44: 10 | O44: 7 | P44: 6 | Q44: 6 | R44: =SUM(F44:Q44) -> 29 | S44: =AVERAGE(F44:Q44) -> 4.8333333 | T44: =U44/S44 -> 45.103448 | U44: =SUM(E44-R44) -> 218
A45: 27736 | B45: 2014 | C45: Petit Verdot | E45: 476 | L45: 10 | M45: 6 | N45: 13 | O45: 6 | P45: 6 | Q45: 11 | R45: =SUM(F45:Q45) -> 52 | S45: =AVERAGE(F45:Q45) -> 8.6666667 | T45: =U45/S45 -> 48.923077 | U45: =SUM(E45-R45) -> 424
A46: 28361 | B46: 2014 | C46: Cab Sauv | E46: 141 | Q46: 1 | R46: =SUM(F46:Q46) -> 1 | S46: =AVERAGE(F46:Q46) -> 1 | T46: =U46/S46 -> 140 | U46: =SUM(E46-R46) -> 140
A47: 22921 | B47: 2014 | C47: Ameritage | E47: 676 | Q47: 1 | R47: =SUM(F47:Q47) -> 1 | S47: =AVERAGE(F47:Q47) -> 1 | T47: =U47/S47 -> 675 | U47: =SUM(E47-R47) -> 675
A48: 34641 | B48: 2014 | C48: Ameritage Res | E48: 372 | Q48: 1 | R48: =SUM(F48:Q48) -> 1 | S48: =AVERAGE(F48:Q48) -> 1 | T48: =U48/S48 -> 371 | U48: =SUM(E48-R48) -> 371
A49: 18004 | B49: 2014 | C49: Mabec | E49: 264 | N49: 6 | O49: 13 | P49: 11 | Q49: 11 | R49: =SUM(F49:Q49) -> 41 | S49: =AVERAGE(F49:Q49) -> 10.25 | T49: =U49/S49 -> 21.756098 | U49: =SUM(E49-R49) -> 223
...

Sheet 2015 Tasting Room and Bulk Wine
A1: Tasting Room | C1: Bottles | D1: Cases | I1: Bulk Wine | J1: Gallons
A2: 2012 | B2: Chard | C2: 3 | D2: =C2/12 -> 0.25 | I2: PM | J2: 1860
A3: 2013 | B3: Chard | C3: 43 | D3: =C3/12 -> 3.5833333 | I3: Traminette | J3: 850
A4: 2014 | B4: Chard | C4: 14 | D4: =C4/12 -> 1.1666667 | I4: Pinot Gris | J4: 825
A5: 2013 | B5: Vio | C5: 28 | D5: =C5/12 -> 2.3333333 | I5: Rose | J5: 800
A6: 2014 | B6: Vio | C6: 33 | D6: =C6/12 -> 2.75 | I6: Delaney | J6: 2650
A7: 2014 | B7: PM | C7: 41 | D7: =C7/12 -> 3.4166667 | I7: Chardonnay | J7: 3700
A8: 2012 | B8: Mer | C8: 35 | D8: =C8/12 -> 2.9166667 | I8: Vio | J8: 2380
A9: 2013 | B9: Mer | C9: 44 | D9: =C9/12 -> 3.6666667 | I9: Cab Sauv | J9: 2360
A10: 2014 | B10: Mer | C10: 9 | D10: =C10/12 -> 0.75 | I10: Mal | J10: 700
A11: 2013 | B11: CF | C11: 37 | D11: =C11/12 -> 3.0833333 | I11: PV/Mal | J11: 1330
A12: 2014 | B12: CF | C12: 21 | D12: =C12/12 -> 1.75 | I12: PV | J12: 1835
A13: 2013 | B13: PV | C13: 18 | D13: =C13/12 -> 1.5 | I13: Cab Franc | J13: 1465
... A17: 2014 | B17: CS | C17: 12 | D17: =C17/12 -> 1 | I17: Norton | J17: 1100
A18: 2013 | B18: AM | C18: 11 | D18: =C18/12 -> 0.91666667
A19: 2014 | B19: AM | C19: 18 | D19: =C19/12 -> 1.5
A20: 2013 | B20: AMR | C20: 21 | D20: =C20/12 -> 1.75
A21: 2014 | B21: AMR | C21: 9 | D21: =C21/12 -> 0.75
A22: 2014 | B22: Farm Use | C22: 57 | D22: =C22/12 -> 4.75
A23: 2013 | B23: CFR | C23: 45 | D23: =C23/12 -> 3.75
A24: 2014 | B24: B Ops | C24: 13 | D24: =C24/12 -> 1.0833333
A25: 2014 | B25: Mal Res | C25: 37 | D25: =C25/12 -> 3.0833333

Sheet 2016
B7: CASES MOVED PER MONTH | V7: CASES MOVED PER MONTH
A8: ABC # | B8: Year | C8: Wine | D8: 2015 Monthly Avg. | E8: 2016 BOY Inventory | F8: Jan | G8: Feb | H8: Mar | I8: Apr | J8: May | K8: Jun | L8: Jul | M8: Aug | N8: Sep | O8: Oct | P8: Nov | Q8: Dec | R8: Totals | S8: 2016 Monthly Avg. | T8: Months Left | U8: Remaining Inventory | V8: Year | W8: Wine
F9: 1
A10: 22384 | B10: 2012 | C10: Merlot | D10: 36 | E10: 208 | F10: 23 | G10: 9 | H10: 8 | I10: 17 | J10: 27 | K10: 16 | L10: 15 | M10: 15 | N10: 23 | O10: 28 | P10: 22 | R10: =SUM(F10:Q10) -> 203 | S10: =IFERROR((AVERAGE(F10:Q10)),0) -> 18.454545 | T10: =IFERROR((U10/S10),0) -> 0.27093596 | U10: =SUM(E10-R10) -> 5 | V10: 2012 | W10: Merlot
A11: 28361 | B11: 2012 | C11: Cab Sauv | D11: 22 | E11: 96 | F11: 22 | G11: 19 | H11: 13 | I11: 26 | J11: 16 | R11: =SUM(F11:Q11) -> 96 | S11: =IFERROR((AVERAGE(F11:Q11)),0) -> 19.2 | T11: =IFERROR((U11/S11),0) -> 0 | U11: =SUM(E11-R11) -> 0 | V11: 2012 | W11: Cab Sauv
A13: 57632 | B13: 2013 | C13: Viognier | D13: 45 | E13: 24 | F13: 21 | G13: 3 | R13: =SUM(F13:Q13) -> 24 | S13: =IFERROR((AVERAGE(F13:Q13)),0) -> 12 | T13: =IFERROR((U13/S13),0) -> 0 | U13: =SUM(E13-R13) -> 0 | V13: 2013 | W13: Viognier
A14: 57630 | B14: 2013 | C14: Chardonnay | D14: 45 | E14: 406 | F14: 32 | G14: 24 | H14: 27 | I14: 49 | J14: =274-227 -> 47 | K14: 75 | L14: 48 | M14: 53 | N14: 51 | R14: =SUM(F14:Q14) -> 406 | S14: =IFERROR((AVERAGE(F14:Q14)),0) -> 45.111111 | T14: =IFERROR((U14/S14),0) -> 0 | U14: =SUM(E14-R14) -> 0 | V14: 2013 | W14: Chardonnay
A15: 22382 | B15: 2013 | C15: Cab Franc | D15: 29 | E15: 190 | F15: 31 | G15: 55 | H15: 25 | I15: 45 | J15: -15 | K15: =49-21 -> 28 | L15: 21 | R15: =SUM(F15:Q15) -> 190 | S15: =IFERROR((AVERAGE(F15:Q15)),0) -> 27.142857 | T15: =IFERROR((U15/S15),0) -> 0 | U15: =SUM(E15-R15) -> 0 | V15: 2013 | W15: Cab Franc
A16: 84802 | B16: 2013 | C16: Cab Franc Res | D16: 18 | E16: 81 | F16: 11 | G16: 4 | H16: 2 | I16: 11 | J16: 8 | K16: 7 | L16: 20 | M16: 6 | N16: 12 | R16: =SUM(F16:Q16) -> 81 | S16: =IFERROR((AVERAGE(F16:Q16)),0) -> 9 | T16: =IFERROR((U16/S16),0) -> 0 | U16: =SUM(E16-R16) -> 0 | V16: 2013 | W16: Cab Franc Res
A17: 22384 | B17: 2013 | C17: Merlot | D17: 36 | E17: 249 | F17: 6 | H17: 1 | I17: 1 | J17: 0 | K17: 0 | L17: 0 | M17: 0 | O17: 8 | P17: 11 | Q17: 18 | R17: =SUM(F17:Q17) -> 45 | S17: =IFERROR((AVERAGE(F17:Q17)),0) -> 4.5 | T17: =IFERROR((U17/S17),0) -> 45.333333 | U17: =SUM(E17-R17) -> 204 | V17: 2013 | W17: Merlot
A18: 27736 | B18: 2013 | C18: Petit Verdot | D18: 22 | E18: 232 | F18: 30 | G18: 28 | H18: 24 | I18: 51 | J18: 33 | K18: 34 | L18: 32 | R18: =SUM(F18:Q18) -> 232 | S18: =IFERROR((AVERAGE(F18:Q18)),0) -> 33.142857 | T18: =IFERROR((U18/S18),0) -> 0 | U18: =SUM(E18-R18) -> 0 | V18: 2013 | W18: Petit Verdot
A19: 28361 | B19: 2013 | C19: Cab Sauv | D19: 22 | E19: 259 | F19: 53 | H19: 5 | J19: 16 | K19: 21 | L19: 22 | M19: 20 | N19: 25 | O19: 10 | P19: 0 | Q19: 0 | R19: =SUM(F19:Q19) -> 172 | S19: =IFERROR((AVERAGE(F19:Q19)),0) -> 17.2 | T19: =IFERROR((U19/S19),0) -> 5.0581395 | U19: =SUM(E19-R19) -> 87 | V19: 2013 | W19: Cab Sauv
A20: 22921 | B20: 2013 | C20: Ameritage | D20: 50 | E20: 478 | F20: 26 | G20: 38 | H20: 32 | I20: 49 | J20: 68 | K20: 55 | L20: 47 | M20: 54 | N20: 43 | O20: 61 | P20: 5 | R20: =SUM(F20:Q20) -> 478 | S20: =IFERROR((AVERAGE(F20:Q20)),0) -> 43.454545 | T20: =IFERROR((U20/S20),0) -> 0 | U20: =SUM(E20-R20) -> 0 | V20: 2013 | W20: Ameritage
A21: 34641 | B21: 2013 | C21: Ameritage Res | D21: 31 | E21: 273 | F21: 22 | G21: 17 | H21: 35 | I21: 35 | J21: 15 | K21: 1 | L21: 25 | M21: 29 | N21: 38 | O21: 18 | P21: 31 | R21: =SUM(F21:Q21) -> 266 | S21: =IFERROR((AVERAGE(F21:Q21)),0) -> 24.181818 | T21: =IFERROR((U21/S21),0) -> 0.28947368 | U21: =SUM(E21-R21) -> 7 | V21: 2013 | W21: Ameritage Res
A23: 11198 | B23: 2014 | C23: Petit Manseng | E23: 59 | F23: 40 | G23: 13 | H23: 6 | R23: =SUM(F23:Q23) -> 59 | S23: =IFERROR((AVERAGE(F23:Q23)),0) -> 19.666667 | T23: =IFERROR((U23/S23),0) -> 0 | U23: =SUM(E23-R23) -> 0 | V23: 2014 | W23: Petit Manseng
A24: 57632 | B24: 2014 | C24: Viognier | E24: 444 | F24: 8 | G24: 18 | H24: 18 | I24: 40 | J24: =360-327 -> 33 | K24: 41 | L24: 49 | M24: 55 | N24: 25 | O24: 28 | P24: 89 | Q24: 0 | R24: =SUM(F24:Q24) -> 404 | S24: =IFERROR((AVERAGE(F24:Q24)),0) -> 33.666667 | T24: =IFERROR((U24/S24),0) -> 1.1881188 | U24: =SUM(E24-R24) -> 40 | V24: 2014 | W24: Viognier
A25: 57630 | B25: 2014 | C25: Chardonnay | E25: 469 | F25: 21 | G25: 9 | I25: 6 | J25: 10 | K25: 2 | L25: 19 | M25: 6 | N25: 17 | O25: 43 | P25: 31 | Q25: 48 | R25: =SUM(F25:Q25) -> 212 | S25: =IFERROR((AVERAGE(F25:Q25)),0) -> 19.272727 | T25: =IFERROR((U25/S25),0) -> 13.334906 | U25: =SUM(E25-R25) -> 257 | V25: 2014 | W25: Chardonnay
A26: 22382 | B26: 2014 | C26: Cab Franc | E26: 308 | F26: 13 | G26: 8 | H26: 4 | I26: 3 | J26: 0 | K26: 0 | L26: 8 | M26: 30 | N26: 39 | O26: 49 | P26: 50 | Q26: 29 | R26: =SUM(F26:Q26) -> 233 | S26: =IFERROR((AVERAGE(F26:Q26)),0) -> 19.416667 | T26: =IFERROR((U26/S26),0) -> 3.8626609 | U26: =SUM(E26-R26) -> 75 | V26: 2014 | W26: Cab Franc
